Workbook

Sheet MATRIZ ENERO 2026
A1: CONCEPTOS | B1: CANTIDAD | C1: VALOR TOTAL
A2: SIN ACUSE | B2: =GETPIVOTDATA("Cuenta de SIN ACUSE",'SIN ACUSES'!$A$3) -> 148 | C2: =GETPIVOTDATA("Suma de Total",'SIN ACUSES'!$A$3) -> 3.8742962e+08
A3: 1 ACUSE | B3: =GETPIVOTDATA("Cuenta de 1 ACUSE",'1 ACUSE'!$A$3) -> 110 | C3: =GETPIVOTDATA("Suma de Total",'1 ACUSE'!$A$3) -> 8.8028017e+08
A4: 2 ACUSES | B4: =GETPIVOTDATA("Cuenta de 2 ACUSE",'2 ACUSES'!$A$3) -> 25 | C4: =GETPIVOTDATA("Suma de Total",'2 ACUSES'!$A$3) -> 2.9529969e+08
A5: 3 ACUSES | B5: =GETPIVOTDATA("Cuenta de 3 ACUSE",'3 ACUSES'!$A$3) -> 187 | C5: =GETPIVOTDATA("Suma de Total",'3 ACUSES'!$A$3) -> 8.1045732e+08
A6: RECHAZADAS | B6: =GETPIVOTDATA("Cuenta de RECHAZADA",'RECHAZADAS '!$A$3) -> 20 | C6: =GETPIVOTDATA("Suma de Total",'RECHAZADAS '!$A$3) -> 4.9694482e+09
A7: PAGAS EN SISTEMA | B7: =GETPIVOTDATA("Cuenta de YA PAGA EN SISTEMA",'PAGAS EN SISTEMA'!$A$3) -> 510 | C7: =GETPIVOTDATA("Suma de Total",'PAGAS EN SISTEMA'!$A$3) -> 4.9694482e+09
B8: =SUM(B2:B7) -> 1000
A10: Tipo de documento | B10: CUFE/CUDE | C10: Folio | D10: Columna1 | E10: Prefijo | F10: Fecha Emisión | G10: Fecha Recepción | H10: NIT Emisor | I10: Nombre Emisor | J10: NIT Receptor | K10: Nombre Receptor | L10: IVA | M10: ICA | N10: IPC | O10: Total | P10: Estado | Q10: Grupo | R10: 1 ACUSE | S10: 2 ACUSE | T10: 3 ACUSE | U10: RECHAZADA | V10: SIN ACUSE | W10: YA PAGA EN SISTEMA | X10: OBSERVACIONES
A11: Factura electrónica | B11: 93074bd740e997c307276fd40785578d26c7149dc6b0d390ff1974e2c5f279a631512f4baded1b8c191af974e7426fa0 | C11: 104623 | D11: =C11-C12 -> -1 | E11: FVE | F11: 06-01-2026 | G11: 06-01-2026 06:51:28 | H11: 900800595 | I11: Provexpress SAS | J11: 900453990 | K11: Fundacion Educativa Colegio Militar Inocencio Chinca Y Su Campus Deportivo | L11: 362673.14 | M11: 0 | N11: 0 | O11: 2271479.1 | P11: Aprobado con notificación | Q11: Emitido | V11: X
A12: Factura electrónica | B12: fe8bb6ec891cf48d8975d938ab00cd2b348b0f748ba29dff5a0fe901ac0fad276781cdc6dabcba91f8833e4adf81bed8 | C12: 104624 | D12: =C12-C13 -> -1 | E12: FVE | F12: 06-01-2026 | G12: 06-01-2026 06:51:33 | H12: 900800595 | I12: Provexpress SAS | J12: 901662739 | K12: Improve Learning SAS | L12: 0 | M12: 0 | N12: 0 | O12: 19962970 | P12: Aprobado con notificación | Q12: Emitido | R12: X
A13: Factura electrónica | B13: 43042fb18294caecd13113422e319846f9c8933dd7316e622324e1c8aae2bc4c1996956121f1462cbdb413faec394a2c | C13: 104625 | D13: =C13-C14 -> -1 | E13: FVE | F13: 06-01-2026 | G13: 06-01-2026 06:51:37 | H13: 900800595 | I13: Provexpress SAS | J13: 830095970 | K13: Distribuidora Y Editora Richmond SAS | L13: 0 | M13: 0 | N13: 0 | O13: 19962970 | P13: Aprobado con notificación | Q13: Emitido | R13: X
A14: Factura electrónica | B14: fe8e0145c40fedcc05a33a04d3a33746824766e163a02d2f2af536217dd3fed77f8431553fcf56eb667d7ca087f3d314 | C14: 104626 | D14: =C14-C15 -> -1 | E14: FVE | F14: 06-01-2026 | G14: 06-01-2026 07:06:50 | H14: 900800595 | I14: Provexpress SAS | J14: 900682841 | K14: Educactiva SAS | L14: 0 | M14: 0 | N14: 0 | O14: 39925940 | P14: Aprobado con notificación | Q14: Emitido | R14: X
A15: Factura electrónica | B15: f463a8aad17f5efc459b4375599b8f48e70411eef7fe456f56fed4a4b644fd9c4a3f13254744d420d0dcc28bac8a949b | C15: 104627 | D15: =C15-C16 -> -1 | E15: FVE | F15: 06-01-2026 | G15: 06-01-2026 07:06:54 | H15: 900800595 | I15: Provexpress SAS | J15: 800024265 | K15: Editorial Santillana SAS | L15: 0 | M15: 0 | N15: 0 | O15: 19962970 | P15: Aprobado con notificación | Q15: Emitido | T15: X
A16: Factura electrónica | B16: dcfba34922f9686abaac32c632009603e447274533d0288c6349667455ee3c93b0c3d55d6fcb999915887ec1d03d3dde | C16: 104628 | D16: =C16-C17 -> -1 | E16: FVE | F16: 06-01-2026 | G16: 06-01-2026 07:06:59 | H16: 900800595 | I16: Provexpress SAS | J16: 800125872 | K16: Keralty SAS | L16: 373204.65 | M16: 0 | N16: 0 | O16: 2337439.6 | P16: Aprobado con notificación | Q16: Emitido | W16: X | X16: PAGA EN EL SISTEMA 27/02/2026
A17: Factura electrónica | B17: b60ba283e3653a668d1a062efda350e75177d7a5418581d079093e09c43c215411b03a513fcd1970a8ae3d68856c525c | C17: 104629 | D17: =C17-C18 -> -1 | E17: FVE | F17: 06-01-2026 | G17: 06-01-2026 07:07:03 | H17: 900800595 | I17: Provexpress SAS | J17: 800125872 | K17: Keralty SAS | L17: 54253.17 | M17: 0 | N17: 0 | O17: 339796.17 | P17: Aprobado con notificación | Q17: Emitido | R17: X
A18: Factura electrónica | B18: 8bb13292ed57504f59b6dd32fe3c1167386d3d3a550bb983be77e3d82c8c52eabed53a35e670da7b286cd7f8553a5c25 | C18: 104630 | D18: =C18-C19 -> -1 | E18: FVE | F18: 06-01-2026 | G18: 06-01-2026 07:07:09 | H18: 900800595 | I18: Provexpress SAS | J18: 800125872 | K18: Keralty SAS | L18: 0 | M18: 0 | N18: 0 | O18: 1865317.4 | P18: Aprobado con notificación | Q18: Emitido | W18: X | X18: PAGA EN EL SISTEMA 27/02/2026
A19: Factura electrónica | B19: 94199b1deb41ac67f09fc244a0d5cff33bd57526447092b061a65f2ef454b083e7cd952ea326fb3a647088bf884322ab | C19: 104631 | D19: =C19-C20 -> -1 | E19: FVE | F19: 06-01-2026 | G19: 06-01-2026 07:07:13 | H19: 900800595 | I19: Provexpress SAS | J19: 800149384 | K19: Clinica Colsanitas SA | L19: 461452.24 | M19: 0 | N19: 0 | O19: 2890148.2 | P19: Aprobado con notificación | Q19: Emitido | R19: X
A20: Factura electrónica | B20: 123fb4dc2236a0301dfe2afab6c2a7ecf9bc7e4e235e3fd48c36092bfb54710a1f1349d4e619f5ec160dc0a6e085b494 | C20: 104632 | D20: =C20-C21 -> -1 | E20: FVE | F20: 06-01-2026 | G20: 06-01-2026 07:07:17 | H20: 900800595 | I20: Provexpress SAS | J20: 800149384 | K20: Clinica Colsanitas SA | L20: 2786643.7 | M20: 0 | N20: 0 | O20: 17453190 | P20: Aprobado con notificación | Q20: Emitido | W20: X | X20: PAGA EN SISTEMA 03/03/2026
A21: Factura electrónica | B21: 08ef3ff49ec6b065c3c6257354597af1d5c4ce3c66fba50d180291e92ad68a276716488a50f2cbe079cbc1ca50810690 | C21: 104633 | D21: =C21-C22 -> -1 | E21: FVE | F21: 06-01-2026 | G21: 06-01-2026 07:07:23 | H21: 900800595 | I21: Provexpress SAS | J21: 800149384 | K21: Clinica Colsanitas SA | L21: 245161.18 | M21: 0 | N21: 0 | O21: 1535483.2 | P21: Aprobado con notificación | Q21: Emitido | W21: X | X21: PAGA EN SISTEMA 03/03/2026
A22: Factura electrónica | B22: f5bde27d37557c9c090b30582c8ecc936ec72c611addfb3b62d676875af59214852e26918d8ed6cd321a37df485edb04 | C22: 104634 | D22: =C22-C23 -> -1 | E22: FVE | F22: 06-01-2026 | G22: 06-01-2026 07:07:27 | H22: 900800595 | I22: Provexpress SAS | J22: 800149384 | K22: Clinica Colsanitas SA | L22: 3203986.5 | M22: 0 | N22: 0 | O22: 20067074 | P22: Aprobado con notificación | Q22: Emitido | W22: X | X22: PAGA EN SISTEMA 03/03/2026
A23: Factura electrónica | B23: f00d2280f33fedf81a2037625549256568358830a6b08bcaaa9c34b2ca94aa821525bccb1aa9f97353a248c595bf87a4 | C23: 104635 | D23: =C23-C24 -> -1 | E23: FVE | F23: 06-01-2026 | G23: 06-01-2026 07:07:31 | H23: 900800595 | I23: Provexpress SAS | J23: 800149384 | K23: Clinica Colsanitas SA | L23: 980644.72 | M23: 0 | N23: 0 | O23: 6141932.7 | P23: Aprobado con notificación | Q23: Emitido | W23: X | X23: PAGA EN SISTEMA 03/03/2026
A24: Factura electrónica | B24: cb8840377dfb85915c7f912b8590e2a38bccb027232de1b397507a138031dc6b9aa3704d36144a09d379368806aa9ab3 | C24: 104636 | D24: =C24-C25 -> -1 | E24: FVE | F24: 06-01-2026 | G24: 06-01-2026 07:07:36 | H24: 900800595 | I24: Provexpress SAS | J24: 800149384 | K24: Clinica Colsanitas SA | L24: 103020.47 | M24: 0 | N24: 0 | O24: 645233.47 | P24: Aprobado con notificación | Q24: Emitido | W24: X | X24: PAGA EN SISTEMA 03/03/2026
A25: Factura electrónica | B25: a91b5f70e0de3354a0dfe3a44b5c5fe4b2e1bc3fd486f558f969a550843c8b9a24f63bc4f97a861d9df1243f19aa0622 | C25: 104637 | D25: =C25-C26 -> -1 | E25: FVE | F25: 06-01-2026 | G25: 06-01-2026 07:22:47 | H25: 900800595 | I25: Provexpress SAS | J25: 800149384 | K25: Clinica Colsanitas SA | L25: 373204.65 | M25: 0 | N25: 0 | O25: 2337439.6 | P25: Aprobado con notificación | Q25: Emitido | W25: X | X25: PAGA EN SISTEMA 03/03/2026
A26: Factura electrónica | B26: fe89b2af2b8522fccfb038194d6defebe93c0a3d32ee838cda4df2be101b2a71373a4ef1c3d916562dd9707cad8fb7a9 | C26: 104638 | D26: =C26-C27 -> -1 | E26: FVE | F26: 06-01-2026 | G26: 06-01-2026 07:22:52 | H26: 900800595 | I26: Provexpress SAS | J26: 800149384 | K26: Clinica Colsanitas SA | L26: 373204.65 | M26: 0 | N26: 0 | O26: 2337439.6 | P26: Aprobado con notificación | Q26: Emitido | W26: X | X26: PAGA EN SISTEMA 03/03/2026
A27: Factura electrónica | B27: 2ddb946c757d00f326058ae6525a094f9d2594ed7ee93cd2e151da61d46fe32e380304feea502b05452e6b9e1f79220a | C27: 104639 | D27: =C27-C28 -> -1 | E27: FVE | F27: 06-01-2026 | G27: 06-01-2026 07:22:57 | H27: 900800595 | I27: Provexpress SAS | J27: 800185773 | K27: Optica Colsanitas SAS | L27: 373204.65 | M27: 0 | N27: 0 | O27: 2337439.6 | P27: Aprobado con notificación | Q27: Emitido | W27: X | X27: PAGA EN SISTEMA 02/03/2026
A28: Factura electrónica | B28: 73f4c12f6bae2fabbd6c3b03947b8ae552cff4e6a5cd1da4e23d3e3d540b61a1fa995defad0d0e481d186d97e2d90a02 | C28: 104640 | D28: =C28-C29 -> -1 | E28: FVE | F28: 06-01-2026 | G28: 06-01-2026 07:23:01 | H28: 900800595 | I28: Provexpress SAS | J28: 860078828 | K28: Compañia De Medicina Prepagada Colsanitas SA | L28: 0 | M28: 0 | N28: 0 | O28: 7390248 | P28: Aprobado con notificación | Q28: Emitido | W28: X | X28: PAGA EN EL SISTEMA 27/02/2026
A29: Factura electrónica | B29: bd84cc834d8531837bb4c601a6b65bf624b904af73e32fb52d6e6fc98a178af80b1ecff368e0eb6b8254583a20096f52 | C29: 104641 | D29: =C29-C30 -> -1 | E29: FVE | F29: 06-01-2026 | G29: 06-01-2026 07:23:06 | H29: 900800595 | I29: Provexpress SAS | J29: 901493815 | K29: Versania Psicosocial Ita SAS | L29: 35764.84 | M29: 0 | N29: 0 | O29: 224000.84 | P29: Aprobado con notificación | Q29: Emitido | T29: X
A30: Factura electrónica | B30: 9165aa2948dc7f7685e0aec43193bada13fe383418f4bedcca9cdeaaf01a20171d6220ccdec430142e6ccc3ac45fd7e4 | C30: 104642 | D30: =C30-C31 -> -1 | E30: FVE | F30: 06-01-2026 | G30: 06-01-2026 07:23:11 | H30: 900800595 | I30: Provexpress SAS | J30: 901485933 | K30: Versania Primera Infancia SAS | L30: 373204.65 | M30: 0 | N30: 0 | O30: 2337439.6 | P30: Aprobado con notificación | Q30: Emitido | V30: X
A31: Factura electrónica | B31: 03f28dafd3dbed1b2c0b824fe85cfa30c5f788139cd3ec4f4fa4eb6048a6de6216046f36ed8e780bbb7cd906edf493f7 | C31: 104643 | D31: =C31-C32 -> -1 | E31: FVE | F31: 06-01-2026 | G31: 06-01-2026 07:23:16 | H31: 900800595 | I31: Provexpress SAS | J31: 830015429 | K31: Salud Ocupacional Sanitas SAS | L31: 0 | M31: 0 | N31: 0 | O31: 4197080.2 | P31: Aprobado con notificación | Q31: Emitido | W31: X | X31: PAGA EN SISTEMA 24/02/2026
A32: Factura electrónica | B32: 1f3c07dd53894bdc21299c529550e2f92aefb200e42877b0ea72546c46c3e02e721232007923318e4426822ea636a215 | C32: 104644 | D32: =C32-C33 -> -1 | E32: FVE | F32: 06-01-2026 | G32: 06-01-2026 07:23:20 | H32: 900800595 | I32: Provexpress SAS | J32: 900022253 | K32: Oftalmosanitas Cali SAS | L32: 57783.75 | M32: 0 | N32: 0 | O32: 361908.75 | P32: Aprobado con notificación | Q32: Emitido | W32: X | X32: PAGA EN SISTEMA 02/03/2026
A33: Factura electrónica | B33: 92303dca04433da38ff8161e03dfa04240cac2808e3a08b77b5d1d6d744c544f12ea9f5b371296395185c3c157c1e5f8 | C33: 104645 | D33: =C33-C34 -> -1 | E33: FVE | F33: 06-01-2026 | G33: 06-01-2026 07:23:25 | H33: 900800595 | I33: Provexpress SAS | J33: 800251440 | K33: Entidad Promotora De Salud Sanitas SAS | L33: 52064.94 | M33: 0 | N33: 0 | O33: 326090.94 | P33: Aprobado con notificación | Q33: Emitido | W33: X | X33: PAGA EN EL SISTEMA 27/02/2026
A34: Factura electrónica | B34: 00e5c221b2161c5e5eeb9a8f365ab3daf0a1dd3c76e44aa317c31511ba0d6e7312506b65604ea9f0f6a4b014d9b57fee | C34: 104646 | D34: =C34-C35 -> -1 | E34: FVE | F34: 06-01-2026 | G34: 06-01-2026 07:23:29 | H34: 900800595 | I34: Provexpress SAS | J34: 901041691 | K34: Centros Medicos Colsanitas S A S | L34: 1017956.2 | M34: 0 | N34: 0 | O34: 6375620.2 | P34: Aprobado con notificación | Q34: Emitido | W34: X | X34: PAGA EN SISTEMA 02/03/2026
A35: Factura electrónica | B35: 3f815376c2f36bcfa0e5c61d64819ec50b42e817157f1e0de0aa1840d7556ab3966474252f1a248ed5cd6b1612fd47db | C35: 104647 | D35: =C35-C36 -> -1 | E35: FVE | F35: 06-01-2026 | G35: 06-01-2026 07:23:35 | H35: 900800595 | I35: Provexpress SAS | J35: 901041691 | K35: Centros Medicos Colsanitas S A S | L35: 508978.08 | M35: 0 | N35: 0 | O35: 3187810.1 | P35: Aprobado con notificación | Q35: Emitido | W35: X | X35: PAGA EN SISTEMA 02/03/2026
A36: Factura electrónica | B36: f49a27d55ffd21f4c84dd47bf754b010cbe78dd20cb9286afc6974937712fe889a53bcaf330457420a089b63cc5822fc | C36: 104648 | D36: =C36-C37 -> -1 | E36: FVE | F36: 06-01-2026 | G36: 06-01-2026 07:38:46 | H36: 900800595 | I36: Provexpress SAS | J36: 900123408 | K36: Compañia De Inversiones Textiles De Moda SAS Texmoda SAS | L36: 342000 | M36: 0 | N36: 0 | O36: 2142000 | P36: Aprobado con notificación | Q36: Emitido | W36: X | X36: PAGA EN SISTEMA 02/03/2026
A37: Factura electrónica | B37: 4016019bc78adc60418353a1ae240ba5ffb72d21d88f1ba887516392e14e085aecb142da6bc93b7e5de2573b0ea1424e | C37: 104649 | D37: =C37-C38 -> -1 | E37: FVE | F37: 06-01-2026 | G37: 06-01-2026 07:38:51 | H37: 900800595 | I37: Provexpress SAS | J37: 900123408 | K37: Compañia De Inversiones Textiles De Moda SAS Texmoda SAS | L37: 96212.2 | M37: 0 | N37: 0 | O37: 602592.2 | P37: Aprobado con notificación | Q37: Emitido | W37: X | X37: PAGA EN SISTEMA 02/03/2026
A38: Factura electrónica | B38: 4157c16dba2959dc4e408697df8fac6a315b5ed30cb67ecf2815104dd24d14c8df531883fca20187bbb62ef1430012c9 | C38: 104650 | D38: =C38-C39 -> -1 | E38: FVE | F38: 06-01-2026 | G38: 06-01-2026 07:38:55 | H38: 900800595 | I38: Provexpress SAS | J38: 860516806 | K38: Permoda Ltda | L38: 271924.2 | M38: 0 | N38: 0 | O38: 1703104.2 | P38: Aprobado con notificación | Q38: Emitido | W38: x | X38: PAGA EN SISTEMA 24/02/2026
A39: Factura electrónica | B39: 378273d8e97e63e12480033faec2a078621c28b36dd2bb847aecda2f7cf1a1a1b5625bb3c317be1337ec9ba3b0c4fd46 | C39: 104651 | D39: =C39-C40 -> -1 | E39: FVE | F39: 06-01-2026 | G39: 06-01-2026 07:39:00 | H39: 900800595 | I39: Provexpress SAS | J39: 860003020 | K39: Banco Bilbao Vizcaya Argentaria Colombia SA | L39: 43701.9 | M39: 0 | N39: 0 | O39: 273711.9 | P39: Aprobado con notificación | Q39: Emitido | W39: X | X39: PAGA EN SISTEMA 13/02/2026
A40: Factura electrónica | B40: 3057c8dfcd8529d4a91df5068b9c80f853017f2c469d333866b2bc770bd948cfe65c6a7bfc372c17c4d1ef5c8f15014d | C40: 104652 | D40: =C40-C41 -> -1 | E40: FVE | F40: 06-01-2026 | G40: 06-01-2026 07:39:05 | H40: 900800595 | I40: Provexpress SAS | J40: 900532450 | K40: Atlantic Quantum Innovations S A S | L40: 595976.8 | M40: 0 | N40: 0 | O40: 3732696.8 | P40: Aprobado con notificación | Q40: Emitido | W40: X | X40: FACTURA PAGA EN EL SISTEMA 23/01/2026
A41: Factura electrónica | B41: 19d3984f41bc5a189a9d34e1ecbc61f7f7fadf13d53f575749f6c5e9f5594563eeca944c2ec62ffb3c20a6813906a5b6 | C41: 104653 | D41: =C41-C42 -> -1 | E41: FVE | F41: 06-01-2026 | G41: 06-01-2026 07:39:09 | H41: 900800595 | I41: Provexpress SAS | J41: 822001390 | K41: Junta De Calificacion De Invalidez Regional Meta | L41: 0 | M41: 0 | N41: 0 | O41: 4105108 | P41: Aprobado con notificación | Q41: Emitido | W41: X | X41: FACTURA PAGA EN EL SISTEMA 30/12/2024
...

Sheet 1 ACUSE
A1: 1 ACUSE | B1: (Varios elementos)
A3: Nombre Receptor | B3: Folio | C3: Cuenta de 1 ACUSE | D3: Suma de Total
A4: Akila S A S | B4: 105537 | C4: 1 | D4: 756840
A5: Total Akila S A S | C5: 1 | D5: 756840
A6: Boticario Colombia S A S | B6: 105186 | C6: 1 | D6: 38679760
B7: 105242 | C7: 1 | D7: 6664000
B8: 105459 | C8: 1 | D8: 7590000
A9: Total Boticario Colombia S A S | C9: 3 | D9: 52933760
A10: Bulkmatic De Colombia SAS | B10: 105594 | C10: 1 | D10: 1035300
A11: Total Bulkmatic De Colombia SAS | C11: 1 | D11: 1035300
A12: Ceramica San Lorenzo Industrial De Colombia SA | B12: 105624 | C12: 1 | D12: 1723726
A13: Total Ceramica San Lorenzo Industrial De Colombia SA | C13: 1 | D13: 1723726
A14: Challenger SAS | B14: 105485 | C14: 1 | D14: 158270
B15: 105555 | C15: 1 | D15: 855729
A16: Total Challenger SAS | C16: 2 | D16: 1013999
A17: Clinica Colsanitas SA | B17: 104631 | C17: 1 | D17: 2890148.2
A18: Total Clinica Colsanitas SA | C18: 1 | D18: 2890148.2
A19: Coala Arquitectura Y Construccion SAS | B19: 105360 | C19: 1 | D19: 407607.83
A20: Total Coala Arquitectura Y Construccion SAS | C20: 1 | D20: 407607.83
A21: Comercializadora Internacional Milpa SA | B21: 105260 | C21: 1 | D21: 8949058.2
B22: 105465 | C22: 1 | D22: 2034031.3
B23: 105584 | C23: 1 | D23: 2490848.5
A24: Total Comercializadora Internacional Milpa SA | C24: 3 | D24: 13473938
A25: Creative Colors SA | B25: 105616 | C25: 1 | D25: 1999200
A26: Total Creative Colors SA | C26: 1 | D26: 1999200
A27: Distribuidora Y Editora Richmond SAS | B27: 104625 | C27: 1 | D27: 19962970
B28: 105189 | C28: 1 | D28: 21122500
B29: 105322 | C29: 1 | D29: 11529841
B30: 105341 | C30: 1 | D30: 6943846.3
A31: Total Distribuidora Y Editora Richmond SAS | C31: 4 | D31: 59559158
A32: Don Maiz SAS | B32: 104878 | C32: 1 | D32: 2543726.6
A33: Total Don Maiz SAS | C33: 1 | D33: 2543726.6
A34: Editorial Santillana SAS | B34: 105238 | C34: 1 | D34: 19876242
B35: 105253 | C35: 1 | D35: 27948158
B36: 105311 | C36: 1 | D36: 38798212
B37: 105345 | C37: 1 | D37: 87650.64
B38: 105356 | C38: 1 | D38: 5301594
A39: Total Editorial Santillana SAS | C39: 5 | D39: 92011856
A40: Educactiva SAS | B40: 104626 | C40: 1 | D40: 39925940
B41: 104745 | C41: 1 | D41: 3841320
...

Sheet 2 ACUSES
A1: 2 ACUSE | B1: (Varios elementos)
A3: Nombre Receptor | B3: Folio | C3: Cuenta de 2 ACUSE | D3: Suma de Total
A4: Administradora Clinica La Colina S A S | B4: 104983 | C4: 1 | D4: 286599.6
A5: Total Administradora Clinica La Colina S A S | C5: 1 | D5: 286599.6
A6: Centros Medicos Colsanitas S A S | B6: 105193 | C6: 1 | D6: 1497215.2
B7: 105436 | C7: 1 | D7: 245996.8
A8: Total Centros Medicos Colsanitas S A S | C8: 2 | D8: 1743212
A9: Ceramica San Lorenzo Industrial De Colombia SA | B9: 104875 | C9: 1 | D9: 418180
A10: Total Ceramica San Lorenzo Industrial De Colombia SA | C10: 1 | D10: 418180
A11: Creative Colors SA | B11: 105479 | C11: 1 | D11: 82110
A12: Total Creative Colors SA | C12: 1 | D12: 82110
A13: Don Maiz SAS | B13: 104874 | C13: 1 | D13: 2013361
B14: 105259 | C14: 1 | D14: 6972388.5
A15: Total Don Maiz SAS | C15: 2 | D15: 8985749.5
A16: Esmeraldas De Los Andes SAS | B16: 105141 | C16: 1 | D16: 4069800
A17: Total Esmeraldas De Los Andes SAS | C17: 1 | D17: 4069800
A18: Esmeraldas Mining Services SAS | B18: 104868 | C18: 1 | D18: 877644.04
B19: 105064 | C19: 1 | D19: 2727475.2
B20: 105065 | C20: 1 | D20: 2727475.2
B21: 105066 | C21: 1 | D21: 4091212.9
A22: Total Esmeraldas Mining Services SAS | C22: 4 | D22: 10423807
A23: Industria Nacional De Gaseosas SA | B23: 105179 | C23: 1 | D23: 23819654
B24: 105180 | C24: 1 | D24: 1.0088126e+08
B25: 105181 | C25: 1 | D25: 1.0088126e+08
A26: Total Industria Nacional De Gaseosas SA | C26: 3 | D26: 2.2558217e+08
A27: Prosegur Vigilancia Y Seguridad Privada LTDA | B27: 104714 | C27: 1 | D27: 809200
B28: 104715 | C28: 1 | D28: 5057500
B29: 104716 | C29: 1 | D29: 85680
B30: 104717 | C30: 1 | D30: 2796500
A31: Total Prosegur Vigilancia Y Seguridad Privada LTDA | C31: 4 | D31: 8748880
A32: Salitre Plaza Centro Comercial Propiedad Horizontal | B32: 105611 | C32: 1 | D32: 218971.9
A33: Total Salitre Plaza Centro Comercial Propiedad Horizontal | C33: 1 | D33: 218971.9
A34: The Muzo Foundation | B34: 105331 | C34: 1 | D34: 4536875
B35: 105494 | C35: 1 | D35: 141610
A36: Total The Muzo Foundation | C36: 2 | D36: 4678485
A37: Mercantil Colpatria SA | B37: 105290 | C37: 1 | D37: 884029
A38: Total Mercantil Colpatria SA | C38: 1 | D38: 884029
A39: Estudios Tecnicos SAS | B39: 105071 | C39: 1 | D39: 9418160.5
A40: Total Estudios Tecnicos SAS | C40: 1 | D40: 9418160.5
A41: Metaza SAS | B41: 105633 | C41: 1 | D41: 19759534
...

Sheet SIN ACUSES
A1: SIN ACUSE | B1: (Varios elementos)
A3: Etiquetas de fila | B3: Cuenta de SIN ACUSE | C3: Suma de Total
A4: 24K Global Logistics SAS | B4: 1 | C4: 3837750
A5: 104781 | B5: 1 | C5: 3837750
A6: ACI Proyectos SAS | B6: 2 | C6: 938838.6
A7: 105067 | B7: 1 | C7: 391438.6
A8: 105455 | B8: 1 | C8: 547400
A9: Agropecuaria La Trinidad Dos SAS | B9: 1 | C9: 1003067.7
A10: 105640 | B10: 1 | C10: 1003067.7
A11: Ajecolombia SAS | B11: 1 | C11: 1487500
A12: 105644 | B12: 1 | C12: 1487500
A13: Aldeas Infantiles SOS Colombia | B13: 1 | C13: 12155850
A14: 105642 | B14: 1 | C14: 12155850
A15: Aquia SAS | B15: 1 | C15: 1428000
... A137: Plasdecor SAS | B137: 2 | C137: 2036350
A138: 105197 | B138: 1 | C138: 1721000
A139: 105589 | B139: 1 | C139: 315350
A140: Thomas Seguridad Integral Ltda | B140: 1 | C140: 1147452.7
A141: 104785 | B141: 1 | C141: 1147452.7
A142: C I Conquers World Trade SAS | B142: 2 | C142: 1203915.3
A143: 104791 | B143: 1 | C143: 1024760.8
A144: 104839 | B144: 1 | C144: 179154.5
A145: Alto Colombia SAS | B145: 2 | C145: 737697.06
A146: 104807 | B146: 1 | C146: 344350
A147: 105220 | B147: 1 | C147: 393347.06
A148: Compañia De La Hacienda De Misiones SA | B148: 1 | C148: 110908
A149: 104858 | B149: 1 | C149: 110908
A150: Power Systems Services Global SAS | B150: 4 | C150: 3078782.5
... A163: Idemia Identity & Security Sucursal Colombia | B163: 1 | C163: 3120890.7
A164: 105021 | B164: 1 | C164: 3120890.7
A165: Clinica Nuestra Señora De La Paz | B165: 1 | C165: 13276259
A166: 105037 | B166: 1 | C166: 13276259
A167: Industrial Hotelera Y Alimentos SAS Dialimentos SAS | B167: 1 | C167: 328440
A168: 105646 | B168: 1 | C168: 328440
A169: Juan Camilo Velasquez Graciano | B169: 1 | C169: 87661.35
A170: 105474 | B170: 1 | C170: 87661.35
A171: Hospitecnica SAS | B171: 1 | C171: 392938
A172: 105094 | B172: 1 | C172: 392938
A173: Hupecol Operating Co LLC | B173: 1 | C173: 322490
A174: 105099 | B174: 1 | C174: 322490
...

Sheet 3 ACUSES
A1: 3 ACUSE | B1: X
A3: Nombre Receptor | B3: Folio | C3: Cuenta de 3 ACUSE | D3: Suma de Total
A4: Adecco Colombia S A | B4: 104934 | C4: 1 | D4: 2353820
A5: Total Adecco Colombia S A | C5: 1 | D5: 2353820
A6: Aei Arquitectura E Interiores SAS | B6: 105250 | C6: 1 | D6: 1999200
A7: Total Aei Arquitectura E Interiores SAS | C7: 1 | D7: 1999200
A8: Applus Norcontrol Colombia Limitada | B8: 104995 | C8: 1 | D8: 293820
A9: Total Applus Norcontrol Colombia Limitada | C9: 1 | D9: 293820
A10: Aquia SAS | B10: 105333 | C10: 1 | D10: 19800
A11: Total Aquia SAS | C11: 1 | D11: 19800
A12: Atlantic Quantum Innovations S A S | B12: 105406 | C12: 1 | D12: 857588.97
B13: 105426 | C13: 1 | D13: 3732696.8
A14: Total Atlantic Quantum Innovations S A S | C14: 2 | D14: 4590285.8
A15: Axure Technologies SA | B15: 104989 | C15: 1 | D15: 6907892.9
B16: 105277 | C16: 1 | D16: 4012680
B17: 105278 | C17: 1 | D17: 2319072
B18: 105513 | C18: 1 | D18: 6425762
B19: 105514 | C19: 1 | D19: 4679400
A20: Total Axure Technologies SA | C20: 5 | D20: 24344807
A21: Bold Co SAS | B21: 104696 | C21: 1 | D21: 22729000
B22: 104697 | C22: 1 | D22: 19611200
A23: Total Bold Co SAS | C23: 2 | D23: 42340200
A24: BR Group SA | B24: 105034 | C24: 1 | D24: 2015793.8
A25: Total BR Group SA | C25: 1 | D25: 2015793.8
A26: Caja Colombiana De Subsidio Familiar Colsubsidio | B26: 105456 | C26: 1 | D26: 788970
B27: 105457 | C27: 1 | D27: 222649
B28: 105572 | C28: 1 | D28: 195914.46
B29: 105579 | C29: 1 | D29: 51765
A30: Total Caja Colombiana De Subsidio Familiar Colsubsidio | C30: 4 | D30: 1259298.5
A31: Caja De Compensacion Familiar Cafam | B31: 105031 | C31: 1 | D31: 23458076
A32: Total Caja De Compensacion Familiar Cafam | C32: 1 | D32: 23458076
A33: Casa De La Valvula SAS | B33: 104956 | C33: 1 | D33: 3314999.7
A34: Total Casa De La Valvula SAS | C34: 1 | D34: 3314999.7
A35: Centros Medicos Colsanitas S A S | B35: 104646 | C35: 1 | D35: 6375620.2
B36: 104647 | C36: 1 | D36: 3187810.1
B37: 104750 | C37: 1 | D37: 163045.47
B38: 104794 | C38: 1 | D38: 3187810.1
B39: 104800 | C39: 1 | D39: 2337439.6
B40: 104801 | C40: 1 | D40: 2337439.6
B41: 104802 | C41: 1 | D41: 7012319
...

Sheet RECHAZADAS 
A1: RECHAZADA | B1: (Todas)
A3: Etiquetas de fila | B3: Cuenta de RECHAZADA | C3: Suma de Total
A4: 24K Global Logistics SAS | C4: 3837750
A5: 104781 | C5: 3837750
A6: Acciones Y Valores SA Comisionista De Bolsa | C6: 1112310.9
A7: 105269 | C7: 59500
A8: 105270 | C8: 126140
A9: 105271 | C9: 149464
A10: 105446 | C10: 777206.85
A11: ACI Proyectos SAS | C11: 938838.6
A12: 105067 | C12: 391438.6
A13: 105455 | C13: 547400
A14: Adecco Colombia S A | C14: 2635850
A15: 104932 | C15: 110670
... A26: 104983 | C26: 286599.6
A27: Aecsa SAS | B27: 1 | C27: 7370860
A28: 105383 | B28: 1 | C28: 7370860
A29: Aei Arquitectura E Interiores SAS | C29: 1999200
A30: 105250 | C30: 1999200
A31: Agroindustrial De Palma Aceitera SA Sucursal Colombia | C31: 1963500
A32: 104952 | C32: 678300
A33: 105226 | C33: 1285200
A34: Agropecuaria La Trinidad Dos SAS | C34: 1003067.7
A35: 105640 | C35: 1003067.7
A36: Ajecolombia SAS | C36: 1487500
A37: 105644 | C37: 1487500
A38: Akila S A S | C38: 756840
A39: 105537 | C39: 756840
A40: Aldeas Infantiles SOS Colombia | C40: 12155850
... A95: 104708 | C95: 64260000
A96: 104709 | C96: 6054720
A97: Bulkmatic De Colombia SAS | C97: 1035300
A98: 105594 | C98: 1035300
A99: Business And Quality Services SAS | C99: 891284.8
A100: 104689 | C100: 891284.8
A101: Caja Colombiana De Subsidio Familiar Colsubsidio | C101: 12074887
A102: 104922 | C102: 48694.8
A103: 104940 | C103: 4636979
A104: 105265 | C104: 212499.49
A105: 105266 | C105: 183855
...

Sheet PAGAS EN SISTEMA
A1: YA PAGA EN SISTEMA | B1: (Todas)
A3: Etiquetas de fila | B3: Cuenta de YA PAGA EN SISTEMA | C3: Suma de Total
A4: 24K Global Logistics SAS | C4: 3837750
A5: 104781 | C5: 3837750
A6: Acciones Y Valores SA Comisionista De Bolsa | B6: 4 | C6: 1112310.9
A7: 105269 | B7: 1 | C7: 59500
A8: 105270 | B8: 1 | C8: 126140
A9: 105271 | B9: 1 | C9: 149464
A10: 105446 | B10: 1 | C10: 777206.85
A11: ACI Proyectos SAS | C11: 938838.6
A12: 105067 | C12: 391438.6
A13: 105455 | C13: 547400
A14: Adecco Colombia S A | B14: 2 | C14: 2635850
A15: 104932 | B15: 1 | C15: 110670
A16: 104933 | B16: 1 | C16: 171360
A17: 104934 | C17: 2353820
A18: Adecco Servicios Colombia S A | B18: 6 | C18: 76250440
A19: 104927 | B19: 1 | C19: 15500940
A20: 104928 | B20: 1 | C20: 387940
A21: 104929 | B21: 1 | C21: 5831000
A22: 104930 | B22: 1 | C22: 110670
A23: 104931 | B23: 1 | C23: 49751520
A24: 105160 | B24: 1 | C24: 4668370
A25: Administradora Clinica La Colina S A S | C25: 286599.6
A26: 104983 | C26: 286599.6
A27: Aecsa SAS | C27: 7370860
A28: 105383 | C28: 7370860
A29: Aei Arquitectura E Interiores SAS | C29: 1999200
A30: 105250 | C30: 1999200
A31: Agroindustrial De Palma Aceitera SA Sucursal Colombia | B31: 2 | C31: 1963500
A32: 104952 | B32: 1 | C32: 678300
A33: 105226 | B33: 1 | C33: 1285200
A34: Agropecuaria La Trinidad Dos SAS | C34: 1003067.7
A35: 105640 | C35: 1003067.7
A36: Ajecolombia SAS | C36: 1487500
A37: 105644 | C37: 1487500
A38: Akila S A S | C38: 756840
A39: 105537 | C39: 756840
A40: Aldeas Infantiles SOS Colombia | C40: 12155850
A41: 105642 | C41: 12155850
...
