Workbook

Sheet ACUSES FEBRERO 2026
A1: CONCEPTOS | B1: CANTIDAD | C1: VALOR TOTAL
A2: SIN ACUSE | B2: =GETPIVOTDATA("Cuenta de SIN ACUSE",'SIN ACUSE'!$A$3) -> 837 | C2: =GETPIVOTDATA("Suma de Total",'SIN ACUSE'!$A$3) -> 5.0649327e+09
A3: 1 ACUSE | B3: =GETPIVOTDATA("Cuenta de 1 ACUSE",'1 ACUSE'!$A$3) -> 428 | C3: =GETPIVOTDATA("Suma de Total",'1 ACUSE'!$A$3) -> 3.1963031e+09
A4: 2 ACUSES | B4: =GETPIVOTDATA("Cuenta de 2 ACUSE",'2 ACUSES'!$A$3) -> 69 | C4: =GETPIVOTDATA("Suma de Total",'2 ACUSES'!$A$3) -> 2.0992611e+08
A5: 3 ACUSES | B5: =GETPIVOTDATA("Cuenta de 3 ACUSE",'3 ACUSES'!$A$3) -> 367 | C5: =GETPIVOTDATA("Suma de Total",'3 ACUSES'!$A$3) -> 1.8084457e+09
A6: RECHAZADAS | B6: =GETPIVOTDATA("Cuenta de RECHAZADA",RECHAZADAS!$A$3) -> 49 | C6: =GETPIVOTDATA("Suma de Total",RECHAZADAS!$A$3) -> 1.3613464e+09
A7: PAGAS EN SISTEMA | B7: =GETPIVOTDATA("Cuenta de YA PAGA EN SISTEMA",'PAGAS EN SISTEMA'!$A$1) -> 192 | C7: =GETPIVOTDATA("Suma de Total",'PAGAS EN SISTEMA'!$A$3) -> 1.37082e+09
B8: =SUM(B2:B7) -> 1942 | C8: =SUM(C2:C7) -> 1.3011774e+10
A11: Tipo de documento | B11: CUFE/CUDE | C11: Folio | D11: Columna1 | E11: Prefijo | F11: Fecha Emisión | G11: Fecha Recepción | H11: NIT Emisor | I11: Nombre Emisor | J11: NIT Receptor | K11: Nombre Receptor | L11: IVA | M11: ICA | N11: IPC | O11: Total | P11: Estado | Q11: Grupo | R11: 1 ACUSE | S11: 2 ACUSE | T11: 3 ACUSE | U11: RECHAZADA | V11: SIN ACUSE | W11: YA PAGA EN SISTEMA | X11: OBSERVACIONES
A12: Factura electrónica | B12: 9e8f28c8532435a346538ba8112c8e9068f13434c11d8c912887c24408c7f4329064f57b5ec8611e6d4110c3c9add36c | C12: 105658 | D12: =C12-C13 -> -1 | E12: FVE | F12: 02-02-2026 | G12: 02-02-2026 10:36:58 | H12: 900800595 | I12: Provexpress SAS | J12: 800066001 | K12: Centro Medico Oftalmologico Y Laboratorio Clinico Andrade Narvaez Sociedad Por Acciones Simplificada | L12: 2997725 | M12: 0 | N12: 0 | O12: 18775225 | P12: Aprobado con notificación | Q12: Emitido | T12: X
A13: Factura electrónica | B13: 707f3324c2985d0956872bed06d68c59cbbcc2638add454dd8e804470260abda9217c0fda5fab5326b848f047bdffde2 | C13: 105659 | D13: =C13-C14 -> -1 | E13: FVE | F13: 02-02-2026 | G13: 02-02-2026 10:37:00 | H13: 900800595 | I13: Provexpress SAS | J13: 902022742 | K13: Andetech SAS | L13: 5455447.6 | M13: 0 | N13: 0 | O13: 34168330 | P13: Aprobado con notificación | Q13: Emitido | V13: X
A14: Factura electrónica | B14: 12c3102ff5193eebafe188694748ffe8ea776ea1d0c9c2f7727e5e3dfa2298822f03257462a42aee8c124014adfa3eb0 | C14: 105660 | D14: =C14-C15 -> -1 | E14: FVE | F14: 02-02-2026 | G14: 02-02-2026 10:37:04 | H14: 900800595 | I14: Provexpress SAS | J14: 860007336 | K14: Caja Colombiana De Subsidio Familiar Colsubsidio | L14: 28044 | M14: 0 | N14: 0 | O14: 175644 | P14: Aprobado con notificación | Q14: Emitido | S14: X
A15: Factura electrónica | B15: 1b08143f21a456ff1082112ede1063a3f7d8c3ea4907763df913c754ea8ec578f79e3e9b5388356277e4c1383fae6589 | C15: 105661 | D15: =C15-C16 -> -1 | E15: FVE | F15: 02-02-2026 | G15: 02-02-2026 10:37:08 | H15: 900800595 | I15: Provexpress SAS | J15: 860007336 | K15: Caja Colombiana De Subsidio Familiar Colsubsidio | L15: 12312 | M15: 0 | N15: 0 | O15: 77112 | P15: Aprobado con notificación | Q15: Emitido | S15: X
A16: Factura electrónica | B16: 63b9538b5e0159ebbd1ffa6e1e357cc1d29dac576871d6010504b8a05e121ca2658b020aea59dc17ac247ae82ef86a66 | C16: 105662 | D16: =C16-C17 -> -1 | E16: FVE | F16: 02-02-2026 | G16: 02-02-2026 10:52:04 | H16: 900800595 | I16: Provexpress SAS | J16: 860007336 | K16: Caja Colombiana De Subsidio Familiar Colsubsidio | L16: 126817.02 | M16: 0 | N16: 0 | O16: 794275.02 | P16: Aprobado con notificación | Q16: Emitido | T16: X
A17: Factura electrónica | B17: 6f60d7737f6aba19c01eb2d54215e6eeb490a59ee0e03fd6806319a0e5c7fda7449b71e51bc932bd52cec1da7fee1a72 | C17: 105663 | D17: =C17-C18 -> -1 | E17: FVE | F17: 02-02-2026 | G17: 02-02-2026 10:52:08 | H17: 900800595 | I17: Provexpress SAS | J17: 860007336 | K17: Caja Colombiana De Subsidio Familiar Colsubsidio | L17: 264689.76 | M17: 0 | N17: 0 | O17: 1657793.8 | P17: Aprobado con notificación | Q17: Emitido | T17: X
A18: Factura electrónica | B18: e5f87f40776c53ce481b92ea82dc58f1ec8eead1822c293727d1b2f1e31cb4dff85f6352280730bf33387aadda0f535f | C18: 105664 | D18: =C18-C19 -> -1 | E18: FVE | F18: 02-02-2026 | G18: 02-02-2026 10:52:16 | H18: 900800595 | I18: Provexpress SAS | J18: 860007336 | K18: Caja Colombiana De Subsidio Familiar Colsubsidio | L18: 18667.5 | M18: 0 | N18: 0 | O18: 116917.5 | P18: Aprobado con notificación | Q18: Emitido | T18: X
A19: Factura electrónica | B19: 638230dc821469761880ec6e47a52c85efec3f32e1331ef28129bed38a92e26a3ea0ed9d233c60bb2eb786deeb537bb3 | C19: 105665 | D19: =C19-C20 -> -1 | E19: FVE | F19: 02-02-2026 | G19: 02-02-2026 10:52:18 | H19: 900800595 | I19: Provexpress SAS | J19: 901847883 | K19: IA4 SAS | L19: 242866.74 | M19: 0 | N19: 0 | O19: 1521112.7 | P19: Aprobado con notificación | Q19: Emitido | T19: X
A20: Factura electrónica | B20: d9d17494e29f3e4a96115842453834c51d6696c4b0465a2d0799d7b22eedf8e286403fd54eb786fa32b8f26d5db19d0a | C20: 105666 | D20: =C20-C21 -> -1 | E20: FVE | F20: 02-02-2026 | G20: 02-02-2026 10:52:23 | H20: 900800595 | I20: Provexpress SAS | J20: 901847883 | K20: IA4 SAS | L20: 59395.52 | M20: 0 | N20: 0 | O20: 372003.52 | P20: Aprobado con notificación | Q20: Emitido | T20: X
A21: Factura electrónica | B21: 24d00dded83330c157318855770d7f7e0ef64f063c7bf120b8e4ef2a27b3bd91eff26e3a5363aa4c4f793766ced0ba1a | C21: 105667 | D21: =C21-C22 -> -1 | E21: FVE | F21: 02-02-2026 | G21: 02-02-2026 10:52:29 | H21: 900800595 | I21: Provexpress SAS | J21: 901847883 | K21: IA4 SAS | L21: 122892 | M21: 0 | N21: 0 | O21: 769692 | P21: Aprobado con notificación | Q21: Emitido | T21: X
A22: Factura electrónica | B22: db47bd5edf1223fe8c65e9bf30fb984d67645639a792d0d5ab7a61bcb719ad28ad87c69d3126b3464535c3939f841da2 | C22: 105668 | D22: =C22-C23 -> -1 | E22: FVE | F22: 02-02-2026 | G22: 02-02-2026 10:52:32 | H22: 900800595 | I22: Provexpress SAS | J22: 901847883 | K22: IA4 SAS | L22: 1139155.6 | M22: 0 | N22: 0 | O22: 7134711.6 | P22: Aprobado con notificación | Q22: Emitido | T22: X
A23: Factura electrónica | B23: 8b1b5684580c86fcd3f2b01ce5f29672849fe794109e9086163afa03db77ae2a3e1e3041df9710f58b791aabf9930645 | C23: 105669 | D23: =C23-C24 -> -1 | E23: FVE | F23: 02-02-2026 | G23: 02-02-2026 10:52:38 | H23: 900800595 | I23: Provexpress SAS | J23: 900024398 | K23: Ecologistica SAS Empresa De Servicios Publicos Ecologistica SAS ESP | L23: 645400.17 | M23: 0 | N23: 0 | O23: 4042243.2 | P23: Aprobado con notificación | Q23: Emitido | T23: X
A24: Factura electrónica | B24: 3a78622c2995dc09ad913647615b08d5324b9c83768ff079309240371ae2deeeb21a41ee555d8e9895b3f2e3aa6852cf | C24: 105670 | D24: =C24-C25 -> -1 | E24: FVE | F24: 02-02-2026 | G24: 02-02-2026 10:52:42 | H24: 900800595 | I24: Provexpress SAS | J24: 900024398 | K24: Ecologistica SAS Empresa De Servicios Publicos Ecologistica SAS ESP | L24: 84091.72 | M24: 0 | N24: 0 | O24: 526679.72 | P24: Aprobado con notificación | Q24: Emitido | T24: X
A25: Factura electrónica | B25: ed59b92615a0b014d73fea5d6de691107185efccb62ab2ed00e640e9826c49ea69395192c59d31840915cd0c81b51606 | C25: 105671 | D25: =C25-C26 -> -1 | E25: FVE | F25: 02-02-2026 | G25: 02-02-2026 10:52:48 | H25: 900800595 | I25: Provexpress SAS | J25: 900916121 | K25: Industria Ambiental SAS | L25: 114001.52 | M25: 0 | N25: 0 | O25: 714009.52 | P25: Aprobado con notificación | Q25: Emitido | T25: X
A26: Factura electrónica | B26: 0837e3626c0ea760f585b2852d6becb00f7bd7a3117bdbc0e8114a6088f0d7f9b0e75124cf0fe4a7e8e2be70c297a445 | C26: 105672 | D26: =C26-C27 -> -1 | E26: FVE | F26: 02-02-2026 | G26: 02-02-2026 10:52:53 | H26: 900800595 | I26: Provexpress SAS | J26: 860525156 | K26: Valrex SAS | L26: 252995.45 | M26: 0 | N26: 0 | O26: 1584550.4 | P26: Aprobado con notificación | Q26: Emitido | T26: X
A27: Factura electrónica | B27: 689557710e31241b29ff0b29810eb5e91ba7f4e86b4521ea1bb000450e71d10287452debcac678fa701146a37671be05 | C27: 105673 | D27: =C27-C28 -> -1 | E27: FVE | F27: 02-02-2026 | G27: 02-02-2026 10:52:57 | H27: 900800595 | I27: Provexpress SAS | J27: 860068182 | K27: Credicorp Capital Colombia SA | L27: 2656777.6 | M27: 0 | N27: 0 | O27: 16639818 | P27: Aprobado con notificación | Q27: Emitido | T27: X
A28: Factura electrónica | B28: 840ead6acb50c9fdca1a66de9f36544e849caf077c067a0e0f590be01c86300a002f03259f0236f73a047d0d3ef79a7f | C28: 105674 | D28: =C28-C29 -> -1 | E28: FVE | F28: 02-02-2026 | G28: 02-02-2026 10:53:02 | H28: 900800595 | I28: Provexpress SAS | J28: 860005114 | K28: Messer Colombia SA | L28: 1039812.4 | M28: 0 | N28: 0 | O28: 6512509.4 | P28: Aprobado con notificación | Q28: Emitido | V28: X
A29: Factura electrónica | B29: 1546001ba61f10f718dd48045184e6b034610f9edbabf38cbc750495a97ef8d4d4d768dfdf2deb0eabe1880d66aac007 | C29: 105675 | D29: =C29-C30 -> -1 | E29: FVE | F29: 02-02-2026 | G29: 02-02-2026 10:53:08 | H29: 900800595 | I29: Provexpress SAS | J29: 900478755 | K29: Centak Export Zf SAS | L29: 64899.06 | M29: 0 | N29: 0 | O29: 406473.06 | P29: Aprobado con notificación | Q29: Emitido | R29: X
A30: Factura electrónica | B30: 6a0786df26cdfccae4892807c267eddf4dd74ca2b517df9d4c290650ce5c20fcf45c6368f5ca7e8a344cb29998494184 | C30: 105676 | D30: =C30-C31 -> -1 | E30: FVE | F30: 02-02-2026 | G30: 02-02-2026 11:08:15 | H30: 900800595 | I30: Provexpress SAS | J30: 900396295 | K30: Merquimia Internacional SAS | L30: 64940.1 | M30: 0 | N30: 0 | O30: 406730.1 | P30: Aprobado con notificación | Q30: Emitido | V30: X
A31: Factura electrónica | B31: 407027706781adf9445faa615550f3fdfece7ea9f36e8f20c5a30a79285702a645b6d0513fbbd9fe67fdae7746a2a352 | C31: 105677 | D31: =C31-C32 -> -1 | E31: FVE | F31: 02-02-2026 | G31: 02-02-2026 11:08:24 | H31: 900800595 | I31: Provexpress SAS | J31: 900319696 | K31: Concentrix Cvg Customer Management Colombia SAS | L31: 170240 | M31: 0 | N31: 0 | O31: 1066240 | P31: Aprobado con notificación | Q31: Emitido | T31: X
A32: Factura electrónica | B32: f3e26d4b1bcd0610159e712e6583bd00de33bb44b0f671daad83919f652c8bd2860d2a7cba15fb09408346a39c2a1a39 | C32: 105678 | D32: =C32-C33 -> -1 | E32: FVE | F32: 02-02-2026 | G32: 02-02-2026 11:23:32 | H32: 900800595 | I32: Provexpress SAS | J32: 800149384 | K32: Clinica Colsanitas SA | L32: 16546.72 | M32: 0 | N32: 0 | O32: 103634.72 | P32: Aprobado con notificación | Q32: Emitido | T32: X
A33: Factura electrónica | B33: 5ff121deada184b911a539ad62e8d0068abb3808b64bb52a19f6c67ac7cc47b4539541180fb0953dd5833c3525d48915 | C33: 105679 | D33: =C33-C34 -> -1 | E33: FVE | F33: 02-02-2026 | G33: 02-02-2026 11:23:35 | H33: 900800595 | I33: Provexpress SAS | J33: 800118776 | K33: Transportes Iceberg De Colombia SA | L33: 160710.36 | M33: 0 | N33: 0 | O33: 1006554.4 | P33: Aprobado con notificación | Q33: Emitido | V33: X
A34: Factura electrónica | B34: 0dbd479dd23ff38de826215780052c0f076049d0d6ebd7eb0f7a96133845c7d1978268de0c6e65e70ca5219f14dc4792 | C34: 105680 | D34: =C34-C35 -> -1 | E34: FVE | F34: 02-02-2026 | G34: 02-02-2026 11:23:40 | H34: 900800595 | I34: Provexpress SAS | J34: 860002183 | K34: Axa Colpatria Seguros De Vida SA | L34: 0 | M34: 0 | N34: 0 | O34: 7931301 | P34: Aprobado con notificación | Q34: Emitido | W34: X | X34: FACTURA PAGA EN EL SISTENMA 27/02/2026
A35: Factura electrónica | B35: 27c22922283a71f64b1932e8bbad5362ed84cb6e1e0082b06411a8e47108253a6a5c2facf77962a18ab22ada84a5cfaa | C35: 105681 | D35: =C35-C36 -> -1 | E35: FVE | F35: 02-02-2026 | G35: 02-02-2026 11:23:45 | H35: 900800595 | I35: Provexpress SAS | J35: 900342297 | K35: Comercializadora Arturo Calle SAS | L35: 133000 | M35: 0 | N35: 0 | O35: 833000 | P35: Aprobado con notificación | Q35: Emitido | T35: X
A36: Factura electrónica | B36: 4ccc65bb341a2509401e409cc6d7b4ea22967beecc2ade9ee1a54a91a1f437cfb302a6783d4e57d33348856ce6065656 | C36: 105682 | D36: =C36-C37 -> -1 | E36: FVE | F36: 02-02-2026 | G36: 02-02-2026 11:23:50 | H36: 900800595 | I36: Provexpress SAS | J36: 900342297 | K36: Comercializadora Arturo Calle SAS | L36: 35351.02 | M36: 0 | N36: 0 | O36: 221409.02 | P36: Aprobado con notificación | Q36: Emitido | T36: X
A37: Factura electrónica | B37: 5d86c7299e6cc22ffd8decd615bd620cb197df3f264ea089ebab9206bc64fca5ef00d19746f7159aded148ae01cdde7d | C37: 105683 | D37: =C37-C38 -> -1 | E37: FVE | F37: 02-02-2026 | G37: 02-02-2026 11:23:54 | H37: 900800595 | I37: Provexpress SAS | J37: 860516806 | K37: Permoda Ltda | L37: 232354.8 | M37: 0 | N37: 0 | O37: 1455274.8 | P37: Aprobado con notificación | Q37: Emitido | R37: X
A38: Factura electrónica | B38: 592150ecd90e6b1eeb467f5112942a5232c144343d3d9c22c2f9f453732f5f736c4e52383acee7975912b1806bf07b26 | C38: 105684 | D38: =C38-C39 -> -1 | E38: FVE | F38: 02-02-2026 | G38: 02-02-2026 11:23:59 | H38: 900800595 | I38: Provexpress SAS | J38: 900033883 | K38: Quimicos Integrales SAS | L38: 104500 | M38: 0 | N38: 0 | O38: 654500 | P38: Aprobado con notificación | Q38: Emitido | W38: X | X38: FACTURA PAGA EN EL SISTEMA 04/02/2026
A39: Factura electrónica | B39: 6b5214da75c4751860b35d87ae01932dda62c351cfc9f3a28422c487ab35ca4a93ede5a495f16710a89cbad71cf34586 | C39: 105685 | D39: =C39-C40 -> -1 | E39: FVE | F39: 02-02-2026 | G39: 02-02-2026 11:24:03 | H39: 900800595 | I39: Provexpress SAS | J39: 900475440 | K39: Sulzer Pumps Colombia SAS | L39: 26600 | M39: 0 | N39: 0 | O39: 166600 | P39: Aprobado con notificación | Q39: Emitido | T39: X
A40: Factura electrónica | B40: 1e13eb14028619fc90de9662e215f9ce12de5c8ce1e5b639541e568f58cf12633f2206e33eea93fa0eb94ccd8a2d49bd | C40: 105686 | D40: =C40-C41 -> -1 | E40: FVE | F40: 02-02-2026 | G40: 02-02-2026 11:24:08 | H40: 900800595 | I40: Provexpress SAS | J40: 860066789 | K40: Universidad El Bosque | L40: 1758450 | M40: 0 | N40: 0 | O40: 11013450 | P40: Aprobado con notificación | Q40: Emitido | T40: X
A41: Factura electrónica | B41: 74b25a619e301ca2af617ba0077e0d2df371884fefcfd8750f86b2e812d4e8580083abcaca65c5c18107d69980fcaca8 | C41: 105687 | D41: =C41-C42 -> -1 | E41: FVE | F41: 02-02-2026 | G41: 02-02-2026 11:24:16 | H41: 900800595 | I41: Provexpress SAS | J41: 901117560 | K41: Epiroc Colombia SAS | L41: 81962.2 | M41: 0 | N41: 0 | O41: 513342.2 | P41: Aprobado con notificación | Q41: Emitido | T41: X
A42: Factura electrónica | B42: 1201e487ebd2f98d4e1c72d96053e9f6f0b273e22b336244566e06bdf5d3997d2783e8cf1d6998c8f80f473333715013 | C42: 105688 | D42: =C42-C43 -> -1 | E42: FVE | F42: 02-02-2026 | G42: 02-02-2026 11:24:19 | H42: 900800595 | I42: Provexpress SAS | J42: 901117560 | K42: Epiroc Colombia SAS | L42: 155069.9 | M42: 0 | N42: 0 | O42: 1349079.9 | P42: Aprobado con notificación | Q42: Emitido | T42: X
...

Sheet Detalle1
A1: Detalles para Cuenta de 1 ACUSE - Nombre Receptor: Aon Risk Services Colombia S A Corredores De Seguros Pero Podra Girar Bajo La Sigla Aon Colombia S A, 1 ACUSE: X
A3: Tipo de documento | B3: CUFE/CUDE | C3: Folio | D3: Columna1 | E3: Prefijo | F3: Fecha Emisión | G3: Fecha Recepción | H3: NIT Emisor | I3: Nombre Emisor | J3: NIT Receptor | K3: Nombre Receptor | L3: IVA | M3: ICA | N3: IPC | O3: Total | P3: Estado | Q3: Grupo | R3: 1 ACUSE | S3: 2 ACUSE | T3: 3 ACUSE | U3: RECHAZADA | V3: SIN ACUSE | W3: YA PAGA EN SISTEMA | X3: OBSERVACIONES
A4: Factura electrónica | B4: b2f69d21b80c359fd38551759cf894c829ae88221bf1a712b4247484aff61a565361b3d2cf582d7efad4b6a8e276e8e0 | C4: 107247 | D4: -1 | E4: FVE | F4: 19-02-2026 | G4: 19-02-2026 12:29:10 | H4: 900800595 | I4: Provexpress SAS | J4: 860069265 | K4: Aon Risk Services Colombia S A Corredores De Seguros Pero Podra Girar Bajo La Sigla Aon Colombia S A | L4: 798000 | M4: 0 | N4: 0 | O4: 4998000 | P4: Aprobado con notificación | Q4: Emitido | R4: X

Sheet 1 ACUSE
A1: 1 ACUSE | B1: (Varios elementos)
A3: Nombre Receptor | B3: Folio | C3: Cuenta de 1 ACUSE | D3: Suma de Total
A4: Adecco Colombia S A | B4: 107031 | C4: 1 | D4: 108290
A5: Total Adecco Colombia S A | C5: 1 | D5: 108290
A6: Adecco Servicios Colombia S A | B6: 107145 | C6: 1 | D6: 27331780
B7: 107325 | C7: 1 | D7: 357595
B8: 107350 | C8: 1 | D8: 4625530
A9: Total Adecco Servicios Colombia S A | C9: 3 | D9: 32314905
A10: Administradora Country SAS | C10: 1 | D10: 10143723
A11: Aecsa SAS | B11: 107421 | C11: 1 | D11: 7370860
A12: Total Aecsa SAS | C12: 1 | D12: 7370860
A13: Aon Risk Services Colombia S A Corredores De Seguros Pero Podra Girar Bajo La Sigla Aon Colombia S A | B13: 107247 | C13: 1 | D13: 4998000
A14: Total Aon Risk Services Colombia S A Corredores De Seguros Pero Podra Girar Bajo La Sigla Aon Colombia S A | C14: 1 | D14: 4998000
A15: Applus Norcontrol Colombia Limitada | B15: 106490 | C15: 1 | D15: 2903659.5
A16: Total Applus Norcontrol Colombia Limitada | C16: 1 | D16: 2903659.5
A17: Asociacion De Egresados De La Universidad De Los Andes Uniandinos | B17: 106128 | C17: 1 | D17: 587021.05
B18: 106867 | C18: 1 | D18: 587021.05
B19: 107054 | C19: 1 | D19: 2771997.9
A20: Total Asociacion De Egresados De La Universidad De Los Andes Uniandinos | C20: 3 | D20: 3946040
A21: Autogermana SAS | B21: 107111 | C21: 1 | D21: 1301979
A22: Total Autogermana SAS | C22: 1 | D22: 1301979
A23: Automundial SA | B23: 105912 | C23: 1 | D23: 196350
B24: 105913 | C24: 1 | D24: 196350
B25: 106117 | C25: 1 | D25: 113050
A26: Total Automundial SA | C26: 3 | D26: 505750
A27: Banco Gnb Sudameris S A | B27: 105726 | C27: 1 | D27: 535500
B28: 106081 | C28: 1 | D28: 267750
A29: Total Banco Gnb Sudameris S A | C29: 2 | D29: 803250
A30: Boticario Colombia S A S | B30: 105806 | C30: 1 | D30: 999600
B31: 105807 | C31: 1 | D31: 4819500
B32: 106549 | C32: 1 | D32: 39139897
A33: Total Boticario Colombia S A S | C33: 3 | D33: 44958997
A34: Carbe SAS | B34: 107176 | C34: 1 | D34: 772905
A35: Total Carbe SAS | C35: 1 | D35: 772905
A36: Carboinsa SAS | B36: 105861 | C36: 1 | D36: 666572.55
B37: 107342 | C37: 1 | D37: 2507288.4
A38: Total Carboinsa SAS | C38: 2 | D38: 3173860.9
A39: Centros Medicos Colsanitas S A S | B39: 107241 | C39: 1 | D39: 370222.09
A40: Total Centros Medicos Colsanitas S A S | C40: 1 | D40: 370222.09
A41: Ceramica San Lorenzo Industrial De Colombia SA | B41: 106370 | C41: 1 | D41: 252945
...

Sheet 2 ACUSES
A1: 2 ACUSE | B1: (Varios elementos)
A3: Nombre Receptor | B3: Folio | C3: Cuenta de 2 ACUSE | D3: Suma de Total
A4: Administradora Clinica La Colina S A S | B4: 106119 | C4: 1 | D4: 3168232.2
A5: Total Administradora Clinica La Colina S A S | C5: 1 | D5: 3168232.2
A6: Administradora Country SAS | B6: 105775 | C6: 1 | D6: 3717189
A7: Total Administradora Country SAS | C7: 1 | D7: 3717189
A8: Caja Colombiana De Subsidio Familiar Colsubsidio | B8: 105660 | C8: 1 | D8: 175644
B9: 105661 | C9: 1 | D9: 77112
A10: Total Caja Colombiana De Subsidio Familiar Colsubsidio | C10: 2 | D10: 252756
A11: Ceramica San Lorenzo Industrial De Colombia SA | B11: 105799 | C11: 1 | D11: 9205413.5
A12: Total Ceramica San Lorenzo Industrial De Colombia SA | C12: 1 | D12: 9205413.5
A13: Colombian Shared Services SAS | B13: 106487 | C13: 1 | D13: 26455350
A14: Total Colombian Shared Services SAS | C14: 1 | D14: 26455350
A15: Confederacion Colombiana De Camaras De Comercio Confecamaras | B15: 106895 | C15: 1 | D15: 317206.4
A16: Total Confederacion Colombiana De Camaras De Comercio Confecamaras | C16: 1 | D16: 317206.4
A17: Congregacion De Hermanas De Caridad Dominicas De La Representacion De La Santisima Virgen | B17: 106624 | C17: 1 | D17: 1165819.2
A18: Total Congregacion De Hermanas De Caridad Dominicas De La Representacion De La Santisima Virgen | C18: 1 | D18: 1165819.2
A19: Don Maiz SAS | B19: 106442 | C19: 1 | D19: 137634.21
B20: 106844 | C20: 1 | D20: 2498533.5
B21: 106845 | C21: 1 | D21: 302600
B22: 106860 | C22: 1 | D22: 624117.36
B23: 107287 | C23: 1 | D23: 291038.3
A24: Total Don Maiz SAS | C24: 5 | D24: 3853923.4
A25: Esmeraldas De Los Andes SAS | B25: 106628 | C25: 1 | D25: 226100
A26: Total Esmeraldas De Los Andes SAS | C26: 1 | D26: 226100
A27: Fitness24seven Colombia S A S | B27: 106865 | C27: 1 | D27: 22947127
A28: Total Fitness24seven Colombia S A S | C28: 1 | D28: 22947127
A29: Flota La Macarena SA | B29: 105777 | C29: 1 | D29: 2420978.7
A30: Total Flota La Macarena SA | C30: 1 | D30: 2420978.7
A31: Geodis Colombia LTDA | B31: 106619 | C31: 1 | D31: 6420000
A32: Total Geodis Colombia LTDA | C32: 1 | D32: 6420000
A33: Idom Consulting Engineering Architecture SAU | B33: 106514 | C33: 1 | D33: 379930.11
A34: Total Idom Consulting Engineering Architecture SAU | C34: 1 | D34: 379930.11
A35: Industria Nacional De Gaseosas SA | B35: 106808 | C35: 1 | D35: 166046.65
B36: 107056 | C36: 1 | D36: 3067848.6
B37: 107210 | C37: 1 | D37: 7224002.1
A38: Total Industria Nacional De Gaseosas SA | C38: 3 | D38: 10457897
A39: Industrias De Refrigeracion Comercial SA Indufrial SA Reorganizacion Empresarial | B39: 106570 | C39: 1 | D39: 498610
A40: Total Industrias De Refrigeracion Comercial SA Indufrial SA Reorganizacion Empresarial | C40: 1 | D40: 498610
A41: Inverleoka SAS | B41: 105770 | C41: 1 | D41: 129234
...

Sheet 3 ACUSES
A1: 3 ACUSE | B1: (Varios elementos)
A3: Nombre Receptor | B3: Folio | C3: Cuenta de 3 ACUSE | D3: Suma de Total
A4: Accion Sociedad Fiduciaria SA | B4: 107102 | C4: 1 | D4: 10390128
A5: Total Accion Sociedad Fiduciaria SA | C5: 1 | D5: 10390128
A6: Adecco Colombia S A | B6: 105729 | C6: 1 | D6: 647360
B7: 105730 | C7: 1 | D7: 64260
B8: 105731 | C8: 1 | D8: 108290
A9: Total Adecco Colombia S A | C9: 3 | D9: 819910
A10: Adecco Servicios Colombia S A | B10: 105739 | C10: 1 | D10: 374850
B11: 105760 | C11: 1 | D11: 541450
B12: 105761 | C12: 1 | D12: 89250
B13: 105762 | C13: 1 | D13: 29110970
B14: 106024 | C14: 1 | D14: 1621970
B15: 106469 | C15: 1 | D15: 5472810
B16: 106470 | C16: 1 | D16: 401030
B17: 106914 | C17: 1 | D17: 714000
B18: 107123 | C18: 1 | D18: 92582
B19: 107124 | C19: 1 | D19: 309400
A20: Total Adecco Servicios Colombia S A | C20: 10 | D20: 38728312
A21: Agrointegral Andina SAS | B21: 106705 | C21: 1 | D21: 4786180
A22: Total Agrointegral Andina SAS | C22: 1 | D22: 4786180
A23: Agunsa Colombia SAS | B23: 106644 | C23: 1 | D23: 71400
B24: 106813 | C24: 1 | D24: 18207000
B25: 106879 | C25: 1 | D25: 559300
A26: Total Agunsa Colombia SAS | C26: 3 | D26: 18837700
A27: Asociacion Para La Enseñanza Aspaen | B27: 105773 | C27: 1 | D27: 393106.98
A28: Total Asociacion Para La Enseñanza Aspaen | C28: 1 | D28: 393106.98
A29: Atp Ingenieria SAS En Reorganizacion | B29: 106462 | C29: 1 | D29: 850000
A30: Total Atp Ingenieria SAS En Reorganizacion | C30: 1 | D30: 850000
A31: Bel Star SA | B31: 106508 | C31: 1 | D31: 8454950
A32: Total Bel Star SA | C32: 1 | D32: 8454950
A33: Bigfoot Colombia SAS | B33: 106279 | C33: 1 | D33: 1772862
A34: Total Bigfoot Colombia SAS | C34: 1 | D34: 1772862
A35: Bold Co SAS | B35: 105918 | C35: 1 | D35: 1234000
B36: 105919 | C36: 1 | D36: 5652500
B37: 105928 | C37: 1 | D37: 6937700
B38: 106067 | C38: 1 | D38: 3427200
B39: 107077 | C39: 1 | D39: 15151675
A40: Total Bold Co SAS | C40: 5 | D40: 32403075
A41: Boydorr SAS | B41: 106592 | C41: 1 | D41: 290419.5
...

Sheet SIN ACUSE
A1: SIN ACUSE | B1: (Varios elementos)
A3: Nombre Receptor | B3: Folio | C3: Cuenta de SIN ACUSE | D3: Suma de Total
A4: 24K Global Logistics SAS | B4: 106603 | C4: 1 | D4: 4606687.5
A5: Total 24K Global Logistics SAS | C5: 1 | D5: 4606687.5
A6: Accion Sociedad Fiduciaria SA | B6: 107562 | C6: 1 | D6: 9473114
B7: 107563 | C7: 1 | D7: 10370969
A8: Total Accion Sociedad Fiduciaria SA | C8: 2 | D8: 19844083
A9: ACI Proyectos SAS | B9: 106402 | C9: 1 | D9: 222789.42
B10: 106904 | C10: 1 | D10: 5116703.7
B11: 107206 | C11: 1 | D11: 916050.11
A12: Total ACI Proyectos SAS | C12: 3 | D12: 6255543.2
A13: Agencia De Aduanas Abc Repecev SAS Nivel 1 | B13: 106083 | C13: 1 | D13: 483140
B14: 106841 | C14: 1 | D14: 345100
B15: 106842 | C15: 1 | D15: 2520420
B16: 106951 | C16: 1 | D16: 357000
B17: 107112 | C17: 1 | D17: 454580
B18: 107230 | C18: 1 | D18: 85680
B19: 107541 | C19: 1 | D19: 724710
B20: 107542 | C20: 1 | D20: 454580
A21: Total Agencia De Aduanas Abc Repecev SAS Nivel 1 | C21: 8 | D21: 5425210
A22: Agricultura Y Servicios S A S | B22: 107113 | C22: 1 | D22: 928200
A23: Total Agricultura Y Servicios S A S | C23: 1 | D23: 928200
A24: Agrointegral Andina SAS | B24: 107114 | C24: 1 | D24: 3088050
A25: Total Agrointegral Andina SAS | C25: 1 | D25: 3088050
A26: Algranel SA | B26: 106825 | C26: 1 | D26: 1563660
A27: Total Algranel SA | C27: 1 | D27: 1563660
A28: Alimentos Thearion Suqa SAS | B28: 106394 | C28: 1 | D28: 838305.06
A29: Total Alimentos Thearion Suqa SAS | C29: 1 | D29: 838305.06
A30: Applus Norcontrol Colombia Limitada | B30: 105763 | C30: 1 | D30: 709047.93
B31: 105764 | C31: 1 | D31: 2903659.5
B32: 105765 | C32: 1 | D32: 1294922.3
B33: 105766 | C33: 1 | D33: 75105.66
B34: 105767 | C34: 1 | D34: 364454.16
B35: 105768 | C35: 1 | D35: 1142084.6
B36: 105769 | C36: 1 | D36: 416500
B37: 106025 | C37: 1 | D37: 221970.7
B38: 106026 | C38: 1 | D38: 63303.24
B39: 106027 | C39: 1 | D39: 260221.83
B40: 106169 | C40: 1 | D40: 114488.8
B41: 106234 | C41: 1 | D41: 499260.93
...

Sheet Detalle2
A1: Detalles para Cuenta de RECHAZADA - Folio: 106231, Nombre Receptor: City Parking SAS, RECHAZADA: X
A3: Tipo de documento | B3: CUFE/CUDE | C3: Folio | D3: Columna1 | E3: Prefijo | F3: Fecha Emisión | G3: Fecha Recepción | H3: NIT Emisor | I3: Nombre Emisor | J3: NIT Receptor | K3: Nombre Receptor | L3: IVA | M3: ICA | N3: IPC | O3: Total | P3: Estado | Q3: Grupo | R3: 1 ACUSE | S3: 2 ACUSE | T3: 3 ACUSE | U3: RECHAZADA | V3: SIN ACUSE | W3: YA PAGA EN SISTEMA | X3: OBSERVACIONES
A4: Factura electrónica | B4: cf0fd6f3c49f1f76926a635cef10106f442ee6dfced1b864a4769c763ffe2d133313cee363ca7547f63a3bab587bb776 | C4: 106231 | D4: -1 | E4: FVE | F4: 05-02-2026 | G4: 05-02-2026 12:16:53 | H4: 900800595 | I4: Provexpress SAS | J4: 830050619 | K4: City Parking SAS | L4: 169130.97 | M4: 0 | N4: 0 | O4: 1059294 | P4: Aprobado con notificación | Q4: Emitido | U4: X

Sheet RECHAZADAS
A1: RECHAZADA | B1: X
A3: Nombre Receptor | B3: Folio | C3: Cuenta de RECHAZADA | D3: Suma de Total
A4: Agencia De Aduanas Abc Repecev SAS Nivel 1 | B4: 107129 | C4: 1 | D4: 483140
A5: Total Agencia De Aduanas Abc Repecev SAS Nivel 1 | C5: 1 | D5: 483140
A6: City Parking SAS | B6: 106231 | C6: 1 | D6: 1059294
B7: 106466 | C7: 1 | D7: 3213000
B8: 106468 | C8: 1 | D8: 2600000
A9: Total City Parking SAS | C9: 3 | D9: 6872294
A10: Comercializadora Colombiana De Carbones Y Coques SAS C I | B10: 106201 | C10: 1 | D10: 1382780
A11: Total Comercializadora Colombiana De Carbones Y Coques SAS C I | C11: 1 | D11: 1382780
A12: Construcciones Arrecife SAS | B12: 106928 | C12: 1 | D12: 246925
A13: Total Construcciones Arrecife SAS | C13: 1 | D13: 246925
A14: Editorial Santillana SAS | B14: 105693 | C14: 1 | D14: 6651505.6
B15: 105694 | C15: 1 | D15: 39432998
B16: 105695 | C16: 1 | D16: 74317600
B17: 105696 | C17: 1 | D17: 44351417
B18: 105697 | C18: 1 | D18: 1.2997053e+08
B19: 105701 | C19: 1 | D19: 22876309
B20: 105703 | C20: 1 | D20: 19887655
B21: 105704 | C21: 1 | D21: 8405629.3
B22: 105706 | C22: 1 | D22: 58579239
B23: 105707 | C23: 1 | D23: 2.6433606e+08
B24: 105708 | C24: 1 | D24: 37015200
B25: 105709 | C25: 1 | D25: 12105470
B26: 105710 | C26: 1 | D26: 13537785
... B34: 106292 | C34: 1 | D34: 67008783
A35: Total Editorial Santillana SAS | C35: 21 | D35: 1.0462382e+09
A36: Fitness24seven Colombia S A S | B36: 106735 | C36: 1 | D36: 12100694
A37: Total Fitness24seven Colombia S A S | C37: 1 | D37: 12100694
A38: Heel Colombia Ltda | B38: 106098 | C38: 1 | D38: 983178
A39: Total Heel Colombia Ltda | C39: 1 | D39: 983178
A40: Industria Nacional De Gaseosas SA | B40: 107051 | C40: 1 | D40: 3067848.6
A41: Total Industria Nacional De Gaseosas SA | C41: 1 | D41: 3067848.6
A42: Kata SAS | B42: 106356 | C42: 1 | D42: 116620
A43: Total Kata SAS | C43: 1 | D43: 116620
A44: Lipesa Colombia SAS | B44: 107315 | C44: 1 | D44: 4281620
B45: 107353 | C45: 1 | D45: 110670
A46: Total Lipesa Colombia SAS | C46: 2 | D46: 4392290
A47: Patrimonios Autonomos Fiduciaria Bancolombia SA Sociedad Fiduciaria | B47: 106491 | C47: 1 | D47: 1.1934655e+08
A48: Total Patrimonios Autonomos Fiduciaria Bancolombia SA Sociedad Fiduciaria | C48: 1 | D48: 1.1934655e+08
...

Sheet PAGAS EN SISTEMA
A1: YA PAGA EN SISTEMA | B1: (Varios elementos)
A3: Nombre Receptor | B3: Folio | C3: Cuenta de YA PAGA EN SISTEMA | D3: Suma de Total
A4: Accion Sociedad Fiduciaria SA | B4: 107443 | C4: 1 | D4: 1234200
A5: Total Accion Sociedad Fiduciaria SA | C5: 1 | D5: 1234200
A6: Agencia De Aduanas Abc Repecev SAS Nivel 1 | B6: 106851 | C6: 1 | D6: 90440
A7: Total Agencia De Aduanas Abc Repecev SAS Nivel 1 | C7: 1 | D7: 90440
A8: Agunsa Colombia SAS | B8: 105894 | C8: 1 | D8: 14458500
B9: 106237 | C9: 1 | D9: 297500
A10: Total Agunsa Colombia SAS | C10: 2 | D10: 14756000
A11: Arcelor Mittal International Colombia SAS | B11: 107044 | C11: 1 | D11: 318298.4
A12: Total Arcelor Mittal International Colombia SAS | C12: 1 | D12: 318298.4
A13: Axa Colpatria Seguros De Vida SA | B13: 105680 | C13: 1 | D13: 7931301
A14: Total Axa Colpatria Seguros De Vida SA | C14: 1 | D14: 7931301
A15: Bmi Colombia Compañia De Seguros De Vida SA | B15: 105948 | C15: 1 | D15: 5434135
B16: 106713 | C16: 1 | D16: 29864985
A17: Total Bmi Colombia Compañia De Seguros De Vida SA | C17: 2 | D17: 35299120
A18: Buk Col SAS | B18: 105733 | C18: 1 | D18: 10829000
A19: Total Buk Col SAS | C19: 1 | D19: 10829000
A20: Cardif Colombia Seguros Generales SA | B20: 107181 | C20: 1 | D20: 6147094.9
A21: Total Cardif Colombia Seguros Generales SA | C21: 1 | D21: 6147094.9
A22: Consejo Profesional De Biologia | B22: 105772 | C22: 1 | D22: 318682
A23: Total Consejo Profesional De Biologia | C23: 1 | D23: 318682
A24: Conservation International Foundation | B24: 106037 | C24: 1 | D24: 940100
B25: 106574 | C25: 1 | D25: 2038470
B26: 106676 | C26: 1 | D26: 279650
A27: Total Conservation International Foundation | C27: 3 | D27: 3258220
A28: Cooperativa Del Magisterio Codema | B28: 106131 | C28: 1 | D28: 19608820
A29: Total Cooperativa Del Magisterio Codema | C29: 1 | D29: 19608820
A30: Cooperativa Nacional De Droguistas Detallistas | B30: 105920 | C30: 1 | D30: 15606857
B31: 105921 | C31: 1 | D31: 2225300
B32: 105922 | C32: 1 | D32: 16476278
B33: 106815 | C33: 1 | D33: 4867385.6
B34: 106816 | C34: 1 | D34: 33422340
B35: 106817 | C35: 1 | D35: 4648140
A36: Total Cooperativa Nacional De Droguistas Detallistas | C36: 6 | D36: 77246301
A37: Corporacion Universitaria De Asturias | B37: 106528 | C37: 1 | D37: 1256640
A38: Total Corporacion Universitaria De Asturias | C38: 1 | D38: 1256640
A39: Croydon Colombia SA | B39: 105989 | C39: 1 | D39: 157997.49
A40: Total Croydon Colombia SA | C40: 1 | D40: 157997.49
A41: Digital Copy Soluciones Digitales SAS | B41: 106691 | C41: 1 | D41: 208250
...
