Workbook

Sheet MATRIZ MARZO
A1: CONCEPTOS | B1: CANTIDAD | C1: VALOR TOTAL
A2: RECHAZADAS | B2: =GETPIVOTDATA("Cuenta de RECHAZADA",RECHAZADAS!$A$3) -> #REF! | C2: =GETPIVOTDATA("Suma de Total",RECHAZADAS!$A$3) -> 1304825.5
A3: 3 ACUSES | B3: =GETPIVOTDATA("Cuenta de 3 ACUSE",'3 ACUSES'!$A$3) -> 117 | C3: =GETPIVOTDATA("Suma de Total",'3 ACUSES'!$A$3) -> 2.2794473e+08
A4: 2 ACUSES | B4: =GETPIVOTDATA("Cuenta de 2 ACUSE",'2 ACUSES'!$A$3) -> 21 | C4: =GETPIVOTDATA("Suma de Total",'2 ACUSES'!$A$3) -> 3.5236346e+08
A5: 1 ACUSE | B5: =GETPIVOTDATA("Cuenta de 1 ACUSE",'1 ACUSE'!$A$3) -> 212 | C5: =GETPIVOTDATA("Suma de Total",'1 ACUSE'!$A$3) -> 1.3496895e+09
A6: SIN ACUSE | B6: =GETPIVOTDATA("Cuenta de SIN ACUSE",'SIN ACUSE'!$A$3) -> 1688 | C6: =GETPIVOTDATA("Suma de Total",'SIN ACUSE'!$A$3) -> 7.1599157e+09
A7: PAGAS EN SISTEMA | B7: =GETPIVOTDATA("Cuenta de YA PAGA EN SISTEMA",'PAGAS EN SISTEMA'!$A$1) -> 0 | C7: =GETPIVOTDATA("Suma de Total",'PAGAS EN SISTEMA'!$A$3) -> 9.0900214e+09
B8: =SUM(B2:B7) -> #REF! | C8: =SUM(C2:C7) -> 1.818124e+10
A10: Tipo de documento | B10: CUFE/CUDE | C10: Folio | D10: Columna1 | E10: Prefijo | F10: Fecha Emisión | G10: Fecha Recepción | H10: NIT Emisor | I10: Nombre Emisor | J10: NIT Receptor | K10: Nombre Receptor | L10: IVA | M10: ICA | N10: Total | O10: Estado | P10: Grupo | Q10: 1 ACUSE | R10: 2 ACUSE | S10: 3 ACUSE | T10: RECHAZADA | U10: SIN ACUSE | V10: YA PAGA EN SISTEMA | W10: OBSERVACIONES | X10: ESTADO2
A11: Factura electrónica | B11: 3758541101d1e2d69232eff132df32489d8ab73ed2619379a6c2ced87d8aa51b47d38ff235acbdc4c1b90768e067b54c | C11: 107597 | D11: =C11-C12 -> -1 | E11: FVE | F11: 02-03-2026 | G11: 02-03-2026 07:03:23 | H11: 900800595 | I11: Provexpress SAS | J11: 890333023 | K11: Siderurgica Del Occidente SAS Sidoc SAS | L11: 54440.7 | M11: 0 | N11: 340970.7 | O11: Aprobado con notificación | P11: Emitido | Q11: x | X11: =IFERROR(VLOOKUP(J10:J1902,[1]sheet1!$A:$K,11,0),"sin acuse") -> Recibo Bien y/o Servicio
A12: Factura electrónica | B12: 4388e89194096fd555bada7968b607e24e1baa4934b6013e84c1c9c5267f72249c419e4187d638adb2817edb17f2436b | C12: 107598 | D12: =C12-C13 -> -1 | E12: FVE | F12: 02-03-2026 | G12: 02-03-2026 07:03:28 | H12: 900800595 | I12: Provexpress SAS | J12: 830513366 | K12: Newsat SAS | L12: 85842 | M12: 0 | N12: 537642 | O12: Aprobado con notificación | P12: Emitido | S12: x | W12: se envia correo al ciente | X12: =IFERROR(VLOOKUP(J11:J1903,[1]sheet1!$A:$K,11,0),"sin acuse") -> sin acuse
A13: Factura electrónica | B13: 35ba599dff3e14960da1a882fdfbc3e4e3b28626fdad619ab3bdf68687447f1b186aa8dfb024e92d621a50d0467fb2e7 | C13: 107599 | D13: =C13-C14 -> -1 | E13: FVE | F13: 02-03-2026 | G13: 02-03-2026 07:03:32 | H13: 900800595 | I13: Provexpress SAS | J13: 860031699 | K13: Vitro Colombia SAS | L13: 20064 | M13: 0 | N13: 125664 | O13: Aprobado con notificación | P13: Emitido | S13: x | X13: =IFERROR(VLOOKUP(J12:J1904,[1]sheet1!$A:$K,11,0),"sin acuse") -> Aceptacion Expresa
A14: Factura electrónica | B14: 1f8378e7c4a9d365bb9e90b8294758634ebe1e07c5511e47d92187e0091f4a58eedbd0352201603c89e91faad7f0ca94 | C14: 107600 | D14: =C14-C15 -> -1 | E14: FVE | F14: 02-03-2026 | G14: 46083.294 | H14: 900800595 | I14: Provexpress SAS | J14: 900396965 | K14: Agroindustrial De Palma Aceitera SA Sucursal Colombia | L14: 23940 | M14: 0 | N14: 149940 | O14: Aprobado con notificación | P14: Emitido | S14: x | X14: =IFERROR(VLOOKUP(J13:J1905,[1]sheet1!$A:$K,11,0),"sin acuse") -> Aceptacion Expresa
A15: Factura electrónica | B15: 42c16285c8279dcf8d699cc6c97a3469ad61694e81fdcb60c72e298331e5bd719a87340798d5b10008b5ec039e6b9018 | C15: 107601 | D15: =C15-C16 -> -1 | E15: FVE | F15: 02-03-2026 | G15: 02-03-2026 07:03:41 | H15: 900800595 | I15: Provexpress SAS | J15: 860023264 | K15: Securitas Colombia SA | L15: 58710 | M15: 0 | N15: 2362710 | O15: Aprobado con notificación | P15: Emitido | Q15: X | X15: =IFERROR(VLOOKUP(J14:J1906,[1]sheet1!$A:$K,11,0),"sin acuse") -> Acuse Recibo
A16: Factura electrónica | B16: c8cf81337c2d266fceab81e803a44b05a480174e1744c2450d324343f46cf679b4c4a1d545c43188e8dee58304420c54 | C16: 107602 | D16: =C16-C17 -> -1 | E16: FVE | F16: 02-03-2026 | G16: 02-03-2026 07:03:46 | H16: 900800595 | I16: Provexpress SAS | J16: 860023264 | K16: Securitas Colombia SA | L16: 58710 | M16: 0 | N16: 2362710 | O16: Aprobado con notificación | P16: Emitido | Q16: X | X16: =IFERROR(VLOOKUP(J15:J1907,[1]sheet1!$A:$K,11,0),"sin acuse") -> Acuse Recibo
A17: Factura electrónica | B17: 276f6ea62b6379d8410370511351a243b8874cb9b5215bc7ced3e2acd6648a83dd02af25519ffa8d7c0cdb0ec58db1b0 | C17: 107603 | D17: =C17-C18 -> -1 | E17: FVE | F17: 02-03-2026 | G17: 02-03-2026 07:03:50 | H17: 900800595 | I17: Provexpress SAS | J17: 860023264 | K17: Securitas Colombia SA | L17: 39140 | M17: 0 | N17: 1575140 | O17: Aprobado con notificación | P17: Emitido | Q17: X | X17: =IFERROR(VLOOKUP(J16:J1908,[1]sheet1!$A:$K,11,0),"sin acuse") -> Acuse Recibo
A18: Factura electrónica | B18: bfc426cad854dea842cb25ca57a25b26129c268dcb41fadba6176369cc73978274b318568f5d22c095017d6a6efd8fe9 | C18: 107604 | D18: =C18-C19 -> -1 | E18: FVE | F18: 02-03-2026 | G18: 02-03-2026 07:03:55 | H18: 900800595 | I18: Provexpress SAS | J18: 860023264 | K18: Securitas Colombia SA | L18: 78280 | M18: 0 | N18: 3150280 | O18: Aprobado con notificación | P18: Emitido | S18: X | X18: =IFERROR(VLOOKUP(J17:J1909,[1]sheet1!$A:$K,11,0),"sin acuse") -> Acuse Recibo
A19: Factura electrónica | B19: 3fb423db44c410d711667dd059b92afc03ac778bcda1663c2302592706c5797d18448414f03a426eb53f9a5bd2249c44 | C19: 107605 | D19: =C19-C20 -> -1 | E19: FVE | F19: 02-03-2026 | G19: 02-03-2026 07:03:59 | H19: 900800595 | I19: Provexpress SAS | J19: 860023264 | K19: Securitas Colombia SA | L19: 19570 | M19: 0 | N19: 787570 | O19: Aprobado con notificación | P19: Emitido | Q19: X | X19: =IFERROR(VLOOKUP(J18:J1910,[1]sheet1!$A:$K,11,0),"sin acuse") -> Acuse Recibo
A20: Factura electrónica | B20: 9973d12d7e8050416731a7bdbef8066c4bd1064a2cb2b2998717fa882f00acc20034e1e284bd341b76ec3b7ebc924fe5 | C20: 107606 | D20: =C20-C21 -> -1 | E20: FVE | F20: 02-03-2026 | G20: 02-03-2026 07:04:06 | H20: 900800595 | I20: Provexpress SAS | J20: 830077655 | K20: Panamericana Outsourcing SA | L20: 129060.73 | M20: 0 | N20: 808327.73 | O20: Aprobado con notificación | P20: Emitido | Q20: X | X20: =IFERROR(VLOOKUP(J19:J1911,[1]sheet1!$A:$K,11,0),"sin acuse") -> Acuse Recibo
A21: Factura electrónica | B21: 444417369daaf98106d64965126ccd1773530080d80c9964bf476d210e8953a4b794367bf215b48702cdfbc07fbc7579 | C21: 107607 | D21: =C21-C22 -> -1 | E21: FVE | F21: 02-03-2026 | G21: 02-03-2026 07:04:10 | H21: 900800595 | I21: Provexpress SAS | J21: 900396965 | K21: Agroindustrial De Palma Aceitera SA Sucursal Colombia | L21: 435480 | M21: 0 | N21: 2727480 | O21: Aprobado con notificación | P21: Emitido | S21: x | X21: =IFERROR(VLOOKUP(J20:J1912,[1]sheet1!$A:$K,11,0),"sin acuse") -> Aceptacion Expresa
A22: Factura electrónica | B22: e4558344b9bd98ca156e7d2b0a80deff43fc2fc7220d681e0e2b91725aab5987a301a9b814f00dfa62916a131fb4ee27 | C22: 107608 | D22: =C22-C23 -> -1 | E22: FVE | F22: 02-03-2026 | G22: 02-03-2026 07:04:16 | H22: 900800595 | I22: Provexpress SAS | J22: 860001615 | K22: Automundial SA | L22: 14250 | M22: 0 | N22: 89250 | O22: Aprobado con notificación | P22: Emitido | Q22: X | X22: =IFERROR(VLOOKUP(J21:J1913,[1]sheet1!$A:$K,11,0),"sin acuse") -> sin acuse
A23: Factura electrónica | B23: f3daba2d454d23e4cf17a3b2f47b236d255acedbfea51ffba10afb32276a117ed956f3d08b58de61d928064bb2319a45 | C23: 107609 | D23: =C23-C24 -> -1 | E23: FVE | F23: 02-03-2026 | G23: 02-03-2026 07:04:20 | H23: 900800595 | I23: Provexpress SAS | J23: 860031699 | K23: Vitro Colombia SAS | L23: 347548 | M23: 0 | N23: 2176748 | O23: Aprobado con notificación | P23: Emitido | S23: X | X23: =IFERROR(VLOOKUP(J22:J1914,[1]sheet1!$A:$K,11,0),"sin acuse") -> Aceptacion Expresa
A24: Factura electrónica | B24: 88149d6d5b109f2d229b117470f3e6c5be0d16e1a4d68566a0c60b312e181d8bb33294b455d028831188e1af3d21d40c | C24: 107610 | D24: =C24-C25 -> -1 | E24: FVE | F24: 02-03-2026 | G24: 02-03-2026 07:04:24 | H24: 900800595 | I24: Provexpress SAS | J24: 860056869 | K24: Cooperativa De Ahorro Y Credito Crediflores | L24: 19760 | M24: 0 | N24: 123760 | O24: Aprobado con notificación | P24: Emitido | S24: x | U24: X | W24: se envia correo al ciente | X24: =IFERROR(VLOOKUP(J23:J1915,[1]sheet1!$A:$K,11,0),"sin acuse") -> sin acuse
A25: Factura electrónica | B25: b24d1dce927474be9e7007de0ce10a3044e4adf059eb438eb5390691b8d9457d46c9680a09873143cf395139e583a8df | C25: 107611 | D25: =C25-C26 -> -1 | E25: FVE | F25: 02-03-2026 | G25: 02-03-2026 07:19:33 | H25: 900800595 | I25: Provexpress SAS | J25: 860513970 | K25: Comercializadora Internacional Milpa SA | L25: 91770 | M25: 0 | N25: 574770 | O25: Aprobado con notificación | P25: Emitido | Q25: X | X25: =IFERROR(VLOOKUP(J24:J1916,[1]sheet1!$A:$K,11,0),"sin acuse") -> Aceptacion Expresa
A26: Factura electrónica | B26: 794a289160cb70e5cf3b4e62da499db166e811ffefa210f9e130344695274e4db23852ea3e055c4a57256c60648dbe30 | C26: 107612 | D26: =C26-C27 -> -1 | E26: FVE | F26: 02-03-2026 | G26: 02-03-2026 07:19:38 | H26: 900800595 | I26: Provexpress SAS | J26: 830109997 | K26: Otto Bock Healthcare Andina SAS | L26: 19000 | M26: 0 | N26: 119000 | O26: Aprobado con notificación | P26: Emitido | U26: X | W26: Se envia correo al cliente | X26: =IFERROR(VLOOKUP(J25:J1917,[1]sheet1!$A:$K,11,0),"sin acuse") -> Sin Evento
A27: Factura electrónica | B27: 1df69dc95a8401394834ab3908c8ece32908743e5ca9cfc1353f2ccc4ebecd2a0bbfd181c4d24c3321015bc632665dad | C27: 107613 | D27: =C27-C28 -> -1 | E27: FVE | F27: 02-03-2026 | G27: 02-03-2026 07:19:42 | H27: 900800595 | I27: Provexpress SAS | J27: 900206480 | K27: Ingetec Ingenieria & Diseños SAS | L27: 4436.5 | M27: 0 | N27: 27786.5 | O27: Aprobado con notificación | P27: Emitido | U27: X | W27: se envia correo al cliente | X27: =IFERROR(VLOOKUP(J26:J1918,[1]sheet1!$A:$K,11,0),"sin acuse") -> Acuse Recibo
A28: Factura electrónica | B28: 4a0a67ffc46ce2dd7439195de79d9e2d8ad3938550d85470c7e64e47bd66ce25b98db2ebb85fc22a6faef129465bef54 | C28: 107614 | D28: =C28-C29 -> -1 | E28: FVE | F28: 02-03-2026 | G28: 02-03-2026 07:19:47 | H28: 900800595 | I28: Provexpress SAS | J28: 860017005 | K28: Challenger SAS | L28: 22800 | M28: 0 | N28: 142800 | O28: Aprobado con notificación | P28: Emitido | Q28: X | X28: =IFERROR(VLOOKUP(J27:J1919,[1]sheet1!$A:$K,11,0),"sin acuse") -> Aceptacion Expresa
A29: Factura electrónica | B29: 89ae5508147e9072a59cfa50447221942213e0b17f8d9fe2385c5f43c17c934e7eacb2072db8b86e577a5cab87e5d8da | C29: 107615 | D29: =C29-C30 -> -1 | E29: FVE | F29: 02-03-2026 | G29: 02-03-2026 07:19:51 | H29: 900800595 | I29: Provexpress SAS | J29: 860031699 | K29: Vitro Colombia SAS | L29: 231800 | M29: 0 | N29: 1451800 | O29: Aprobado con notificación | P29: Emitido | S29: X | X29: =IFERROR(VLOOKUP(J28:J1920,[1]sheet1!$A:$K,11,0),"sin acuse") -> Aceptacion Expresa
A30: Factura electrónica | B30: 035a5722c5509f6b0c11d0c5bf7725d2276e594b727b03e7983c7a425e3d3583d7da89e644544ebee051b85b50a8811d | C30: 107616 | D30: =C30-C31 -> -1 | E30: FVE | F30: 02-03-2026 | G30: 02-03-2026 07:19:56 | H30: 900800595 | I30: Provexpress SAS | J30: 860007336 | K30: Caja Colombiana De Subsidio Familiar Colsubsidio | L30: 31280.46 | M30: 0 | N30: 195914.46 | O30: Aprobado con notificación | P30: Emitido | S30: X | X30: =IFERROR(VLOOKUP(J29:J1921,[1]sheet1!$A:$K,11,0),"sin acuse") -> Aceptacion Expresa
A31: Factura electrónica | B31: 6c8ebfc79fdfdc5b3dca3921a4d55c4d837b01564d977dc46b5c59f8633ca4f52193d8ed2f9c8220962b87152e8fcff7 | C31: 107617 | D31: =C31-C32 -> -1 | E31: FVE | F31: 02-03-2026 | G31: 02-03-2026 07:20:00 | H31: 900800595 | I31: Provexpress SAS | J31: 860007336 | K31: Caja Colombiana De Subsidio Familiar Colsubsidio | L31: 31472.36 | M31: 0 | N31: 197116.36 | O31: Aprobado con notificación | P31: Emitido | S31: X | X31: =IFERROR(VLOOKUP(J30:J1922,[1]sheet1!$A:$K,11,0),"sin acuse") -> Aceptacion Expresa
A32: Factura electrónica | B32: 2bcefacbb756dea198f9c3fc8cdd287d213dff148b6301a60990edb9e1b66a015154c03db14dd52e7beefa945d71c048 | C32: 107618 | D32: =C32-C33 -> -1 | E32: FVE | F32: 02-03-2026 | G32: 02-03-2026 07:20:05 | H32: 900800595 | I32: Provexpress SAS | J32: 860007336 | K32: Caja Colombiana De Subsidio Familiar Colsubsidio | L32: 31472.36 | M32: 0 | N32: 197116.36 | O32: Aprobado con notificación | P32: Emitido | S32: X | X32: =IFERROR(VLOOKUP(J31:J1923,[1]sheet1!$A:$K,11,0),"sin acuse") -> Aceptacion Expresa
A33: Factura electrónica | B33: 73b318602f0ff45d2295099457ead2d23388fc157a97341c1a02b2b02bf87d84d547c378ee62b24c4418644a363ceed8 | C33: 107619 | D33: =C33-C34 -> -1 | E33: FVE | F33: 02-03-2026 | G33: 02-03-2026 07:20:37 | H33: 900800595 | I33: Provexpress SAS | J33: 860007336 | K33: Caja Colombiana De Subsidio Familiar Colsubsidio | L33: 31472.36 | M33: 0 | N33: 197116.36 | O33: Aprobado con notificación | P33: Emitido | S33: X | X33: =IFERROR(VLOOKUP(J32:J1924,[1]sheet1!$A:$K,11,0),"sin acuse") -> Aceptacion Expresa
A34: Factura electrónica | B34: a789a5dee17a4afa6e372b691115ab6adc630483baff6b5b66fd22870a243430602422bb7eafc0754efc0482c4ba8ed5 | C34: 107620 | D34: =C34-C35 -> -1 | E34: FVE | F34: 02-03-2026 | G34: 02-03-2026 07:20:37 | H34: 900800595 | I34: Provexpress SAS | J34: 860007336 | K34: Caja Colombiana De Subsidio Familiar Colsubsidio | L34: 31280.46 | M34: 0 | N34: 195914.46 | O34: Aprobado con notificación | P34: Emitido | S34: X | X34: =IFERROR(VLOOKUP(J33:J1925,[1]sheet1!$A:$K,11,0),"sin acuse") -> Aceptacion Expresa
A35: Factura electrónica | B35: 51e0dd67f709168072945bd54d6515ffe381fea0a407a9d01df003a0a8fd1cbafcddb7d008690745f89ea758e8342b33 | C35: 107621 | D35: =C35-C36 -> -1 | E35: FVE | F35: 02-03-2026 | G35: 02-03-2026 07:20:37 | H35: 900800595 | I35: Provexpress SAS | J35: 860007336 | K35: Caja Colombiana De Subsidio Familiar Colsubsidio | L35: 31280.46 | M35: 0 | N35: 195914.46 | O35: Aprobado con notificación | P35: Emitido | S35: X | X35: =IFERROR(VLOOKUP(J34:J1926,[1]sheet1!$A:$K,11,0),"sin acuse") -> Aceptacion Expresa
A36: Factura electrónica | B36: 555d5027e50dd73dee48cf73fed4ef228a78a50184b8cae1abb9b0911e6becdc462863cc2b32be64393238c1a4702790 | C36: 107622 | D36: =C36-C37 -> -1 | E36: FVE | F36: 02-03-2026 | G36: 02-03-2026 07:20:34 | H36: 900800595 | I36: Provexpress SAS | J36: 860007336 | K36: Caja Colombiana De Subsidio Familiar Colsubsidio | L36: 29687.5 | M36: 0 | N36: 185937.5 | O36: Aprobado con notificación | P36: Emitido | S36: X | X36: =IFERROR(VLOOKUP(J35:J1927,[1]sheet1!$A:$K,11,0),"sin acuse") -> Aceptacion Expresa
A37: Factura electrónica | B37: e163522c5da6e5452f1a1f396cb5f82bd65653d401a9fcd84e8cc9013c648edc515d0724fb756257950976cb117ab4dc | C37: 107623 | D37: =C37-C38 -> -1 | E37: FVE | F37: 02-03-2026 | G37: 02-03-2026 07:20:37 | H37: 900800595 | I37: Provexpress SAS | J37: 860007336 | K37: Caja Colombiana De Subsidio Familiar Colsubsidio | L37: 29141.06 | M37: 0 | N37: 182515.06 | O37: Aprobado con notificación | P37: Emitido | S37: X | X37: =IFERROR(VLOOKUP(J36:J1928,[1]sheet1!$A:$K,11,0),"sin acuse") -> Aceptacion Expresa
A38: Factura electrónica | B38: a9ffb6ffa5bb680aafa918cb7ad350a6d056965f07f090ed29c55fc8c00c9f65b62f0c474dfe05ac383b5c4e070111c4 | C38: 107624 | D38: =C38-C39 -> -1 | E38: FVE | F38: 02-03-2026 | G38: 02-03-2026 07:20:37 | H38: 900800595 | I38: Provexpress SAS | J38: 901847883 | K38: IA4 SAS | L38: 347600.82 | M38: 0 | N38: 2177078.8 | O38: Aprobado con notificación | P38: Emitido | Q38: X | X38: =IFERROR(VLOOKUP(J37:J1929,[1]sheet1!$A:$K,11,0),"sin acuse") -> Aceptacion Expresa
A39: Factura electrónica | B39: 6e29fef0a27509b6ee27040e09b192b818547f713d210226e06480f1df8481c71dab146c29cf461c70554cd1f221fade | C39: 107625 | D39: =C39-C40 -> -1 | E39: FVE | F39: 02-03-2026 | G39: 02-03-2026 07:20:39 | H39: 900800595 | I39: Provexpress SAS | J39: 800201648 | K39: Asesorias Servicios Ecologicos E Industriales SAS | L39: 78983.25 | M39: 0 | N39: 527406.25 | O39: Aprobado con notificación | P39: Emitido | Q39: X | X39: =IFERROR(VLOOKUP(J38:J1930,[1]sheet1!$A:$K,11,0),"sin acuse") -> Aceptacion Expresa
A40: Factura electrónica | B40: 4dddb3e5c086a8fe3e4479560eddb501d61277f788fdcfbb270de8365276bf382c90c693b472f1b72c3c972f9e284290 | C40: 107626 | D40: =C40-C41 -> -1 | E40: FVE | F40: 02-03-2026 | G40: 02-03-2026 07:20:42 | H40: 900800595 | I40: Provexpress SAS | J40: 830111257 | K40: Grupo Empresarial En Linea S.A. | L40: 89870 | M40: 0 | N40: 7778870 | O40: Aprobado con notificación | P40: Emitido | S40: X | X40: =IFERROR(VLOOKUP(J39:J1931,[1]sheet1!$A:$K,11,0),"sin acuse") -> Aceptacion Expresa
A41: Factura electrónica | B41: bf1f80ad8fd6439b6acc8281b55a9ae4d6f9c1e75a4e70846e3e2fce7a6a179b577e69b9521b6f8b3bc36129e0b4cc94 | C41: 107627 | D41: =C41-C42 -> -1 | E41: FVE | F41: 02-03-2026 | G41: 02-03-2026 07:35:50 | H41: 900800595 | I41: Provexpress SAS | J41: 860007336 | K41: Caja Colombiana De Subsidio Familiar Colsubsidio | L41: 49495 | M41: 0 | N41: 309995 | O41: Aprobado con notificación | P41: Emitido | S41: X | X41: =IFERROR(VLOOKUP(J40:J1932,[1]sheet1!$A:$K,11,0),"sin acuse") -> Aceptacion Expresa
...

Sheet 1 ACUSE
A1: 1 ACUSE | B1: (Varios elementos)
A3: Nombre Receptor | B3: Folio | C3: Cuenta de 1 ACUSE | D3: Suma de Total
A4: Actual Colombia Inmobiliaria SAS | B4: 108057 | C4: 1 | D4: 1392300
A5: Total Actual Colombia Inmobiliaria SAS | C5: 1 | D5: 1392300
A6: Adecco Colombia S A | C6: 1 | D6: 433160
A7: Administradora Clinica La Colina S A S | B7: 108313 | C7: 1 | D7: 3525589.2
A8: Total Administradora Clinica La Colina S A S | C8: 1 | D8: 3525589.2
A9: Administradora Country SAS | B9: 107955 | C9: 1 | D9: 1155180.6
A10: Total Administradora Country SAS | C10: 1 | D10: 1155180.6
A11: Alimentos Balanceados Tequendama SA Albateq SA | B11: 108371 | C11: 1 | D11: 742443.38
A12: Total Alimentos Balanceados Tequendama SA Albateq SA | C12: 1 | D12: 742443.38
A13: Automundial SA | B13: 107608 | C13: 1 | D13: 89250
B14: 108373 | C14: 1 | D14: 92344
A15: Total Automundial SA | C15: 2 | D15: 181594
A16: Avidesa De Occidente SA | B16: 108158 | C16: 1 | D16: 119952
B17: 108249 | C17: 1 | D17: 139322.82
A18: Total Avidesa De Occidente SA | C18: 2 | D18: 259274.82
A19: Banco Mundo Mujer SA O Mundo Mujer El Banco De La Comunidad O Mundo Mujer | B19: 107630 | C19: 1 | D19: 362581.1
A20: Total Banco Mundo Mujer SA O Mundo Mujer El Banco De La Comunidad O Mundo Mujer | C20: 1 | D20: 362581.1
A21: Caja De Compensacion Familiar Compensar | B21: 108125 | C21: 1 | D21: 342720
A22: Total Caja De Compensacion Familiar Compensar | C22: 1 | D22: 342720
A23: Ceramica San Lorenzo Industrial De Colombia SA | B23: 107889 | C23: 1 | D23: 158508
A24: Total Ceramica San Lorenzo Industrial De Colombia SA | C24: 1 | D24: 158508
A25: Clinica Colsanitas SA | B25: 107906 | C25: 1 | D25: 15460624
A26: Total Clinica Colsanitas SA | C26: 1 | D26: 15460624
A27: Colinagro SA | B27: 108151 | C27: 1 | D27: 119000
A28: Total Colinagro SA | C28: 1 | D28: 119000
A29: Comercializadora Arturo Calle SAS | B29: 107800 | C29: 1 | D29: 116887.75
B30: 107920 | C30: 1 | D30: 124950
B31: 108766 | C31: 1 | D31: 1095038
A32: Total Comercializadora Arturo Calle SAS | C32: 3 | D32: 1336875.8
A33: Comercializadora Internacional Milpa SA | B33: 107611 | C33: 1 | D33: 574770
B34: 107694 | C34: 1 | D34: 238000
B35: 107892 | C35: 1 | D35: 18204620
B36: 108239 | C36: 1 | D36: 1581557.6
A37: Total Comercializadora Internacional Milpa SA | C37: 4 | D37: 20598948
A38: Compañia Colombiana De Seguridad Transbank LTDA | B38: 108114 | C38: 1 | D38: 678300
A39: Total Compañia Colombiana De Seguridad Transbank LTDA | C39: 1 | D39: 678300
A40: Confederacion Colombiana De Camaras De Comercio Confecamaras | B40: 108335 | C40: 1 | D40: 338068.29
B41: 108336 | C41: 1 | D41: 766360
...

Sheet 2 ACUSES
A1: 2 ACUSE | B1: (Varios elementos)
A3: Nombre Receptor | B3: Folio | C3: Cuenta de 2 ACUSE | D3: Suma de Total
A4: Caja Colombiana De Subsidio Familiar Colsubsidio | B4: 108304 | C4: 1 | D4: 963543
A5: Total Caja Colombiana De Subsidio Familiar Colsubsidio | C5: 1 | D5: 963543
A6: Ferricentros SAS | B6: 107785 | C6: 1 | D6: 1387596.4
B7: 107832 | C7: 1 | D7: 2156624.4
B8: 107847 | C8: 1 | D8: 1661548
A9: Total Ferricentros SAS | C9: 3 | D9: 5205768.8
A10: Flota La Macarena SA | B10: 107959 | C10: 1 | D10: 1221073.2
A11: Total Flota La Macarena SA | C11: 1 | D11: 1221073.2
A12: Novasoft S A S | B12: 108230 | C12: 1 | D12: 4816663
A13: Total Novasoft S A S | C13: 1 | D13: 4816663
A14: Universidad De La Sabana | B14: 107765 | C14: 1 | D14: 1055000
A15: Total Universidad De La Sabana | C15: 1 | D15: 1055000
A16: Agroindustrial De Palma Aceitera SA Sucursal Colombia | B16: 107967 | C16: 1 | D16: 671160
A17: Total Agroindustrial De Palma Aceitera SA Sucursal Colombia | C17: 1 | D17: 671160
A18: Colombian Shared Services SAS | B18: 107896 | C18: 1 | D18: 905590
A19: Total Colombian Shared Services SAS | C19: 1 | D19: 905590
A20: Banco Jpmorgan Colombia SA | B20: 107653 | C20: 1 | D20: 720426
A21: Total Banco Jpmorgan Colombia SA | C21: 1 | D21: 720426
A22: Industria Nacional De Gaseosas SA | B22: 107687 | C22: 1 | D22: 2.7847637e+08
B23: 107760 | C23: 1 | D23: 8723594.9
B24: 107937 | C24: 1 | D24: 35257.32
A25: Total Industria Nacional De Gaseosas SA | C25: 3 | D25: 2.8723522e+08
A26: Palmas De Tumaco SAS | B26: 107704 | C26: 1 | D26: 890838.76
A27: Total Palmas De Tumaco SAS | C27: 1 | D27: 890838.76
A28: Hire Horatio Co S A S | B28: 107810 | C28: 1 | D28: 16213155
A29: Total Hire Horatio Co S A S | C29: 1 | D29: 16213155
A30: C I Union De Bananeros De Uraba SA Uniban | B30: 107752 | C30: 1 | D30: 3430216.6
B31: 107753 | C31: 1 | D31: 6120165.2
A32: Total C I Union De Bananeros De Uraba SA Uniban | C32: 2 | D32: 9550381.9
A33: Fundacion Universidad Del Norte | B33: 107827 | C33: 1 | D33: 437920
A34: Total Fundacion Universidad Del Norte | C34: 1 | D34: 437920
A35: Pc Quick SAS | B35: 108160 | C35: 1 | D35: 16207800
A36: Total Pc Quick SAS | C36: 1 | D36: 16207800
A37: Oftalmos SA | B37: 108196 | C37: 1 | D37: 1142400
B38: 108268 | C38: 1 | D38: 5126520
A39: Total Oftalmos SA | C39: 2 | D39: 6268920
A40: Total general | C40: 21 | D40: 3.5236346e+08

Sheet 3 ACUSES
A1: 3 ACUSE | B1: (Varios elementos)
A3: Nombre Receptor | B3: Folio | C3: Cuenta de 3 ACUSE | D3: Suma de Total
A4: Adecco Servicios Colombia S A | B4: 108019 | C4: 1 | D4: 387940
B5: 108140 | C5: 1 | D5: 3855600
A6: Total Adecco Servicios Colombia S A | C6: 2 | D6: 4243540
A7: Alambres Y Mallas SAS | B7: 108082 | C7: 1 | D7: 7681154.9
A8: Total Alambres Y Mallas SAS | C8: 1 | D8: 7681154.9
A9: Asociacion Para La Enseñanza Aspaen | B9: 108161 | C9: 1 | D9: 1141099.3
A10: Total Asociacion Para La Enseñanza Aspaen | C10: 1 | D10: 1141099.3
A11: Bmi Colombia Compañia De Seguros De Vida SA | B11: 107805 | C11: 1 | D11: 476000
A12: Total Bmi Colombia Compañia De Seguros De Vida SA | C12: 1 | D12: 476000
A13: Boydorr SAS | B13: 107835 | C13: 1 | D13: 428638
A14: Total Boydorr SAS | C14: 1 | D14: 428638
A15: Cadena Comercial Oxxo Colombia SAS | B15: 107891 | C15: 1 | D15: 802739
A16: Total Cadena Comercial Oxxo Colombia SAS | C16: 1 | D16: 802739
A17: Caja Colombiana De Subsidio Familiar Colsubsidio | B17: 107616 | C17: 1 | D17: 195914.46
B18: 107617 | C18: 1 | D18: 197116.36
B19: 107618 | C19: 1 | D19: 197116.36
B20: 107619 | C20: 1 | D20: 197116.36
B21: 107620 | C21: 1 | D21: 195914.46
B22: 107621 | C22: 1 | D22: 195914.46
B23: 107622 | C23: 1 | D23: 185937.5
B24: 107623 | C24: 1 | D24: 182515.06
B25: 107627 | C25: 1 | D25: 309995
B26: 107628 | C26: 1 | D26: 94724
B27: 107629 | C27: 1 | D27: 284172
B28: 107818 | C28: 1 | D28: 174216
B29: 107819 | C29: 1 | D29: 1046605
... B36: 108205 | C36: 1 | D36: 350752.5
A37: Total Caja Colombiana De Subsidio Familiar Colsubsidio | C37: 20 | D37: 4839763.3
A38: Centros Medicos Colsanitas S A S | B38: 107675 | C38: 1 | D38: 2337439.6
B39: 107676 | C39: 1 | D39: 4674879.3
A40: Total Centros Medicos Colsanitas S A S | C40: 2 | D40: 7012318.9
A41: Chevyplan SA Sociedad Administradora De Planes De Autofinanciamiento Comercial | B41: 107825 | C41: 1 | D41: 1650530
A42: Total Chevyplan SA Sociedad Administradora De Planes De Autofinanciamiento Comercial | C42: 1 | D42: 1650530
A43: Clinica Colsanitas SA | B43: 107677 | C43: 1 | D43: 2337439.6
B44: 107678 | C44: 1 | D44: 2337439.6
B45: 107679 | C45: 1 | D45: 2337439.6
B46: 107680 | C46: 1 | D46: 3187810.1
B47: 107681 | C47: 1 | D47: 3187810.1
...

Sheet RECHAZADAS
A1: RECHAZADA | B1: X
A3: Folio | B3: Nombre Receptor | C3: Suma de Total
A4: 107871 | B4: Idom Consulting Engineering Architecture SAU | C4: 107975.84
A5: Total 107871 | C5: 107975.84
A6: 108054 | B6: Salud Total Entidad Promotora De Salud Del Regimen Contributivo Y Del Regimen Subsidiado SA | C6: 829350.27
A7: Total 108054 | C7: 829350.27
A8: 108143 | B8: Indra Colombia SAS | C8: 321300
A9: Total 108143 | C9: 321300
A10: 108497 | B10: Caja Colombiana De Subsidio Familiar Colsubsidio | C10: 46199.37
A11: Total 108497 | C11: 46199.37
A12: Total general | C12: 1304825.5

Sheet SIN ACUSE
A1: SIN ACUSE | B1: (Varios elementos)
A3: Nombre Receptor | B3: Folio | C3: Cuenta de SIN ACUSE | D3: Suma de Total
A4: 24K Global Logistics SAS | B4: 108175 | C4: 1 | D4: 5408550
B5: 108503 | C5: 1 | D5: 522410
B6: 108623 | C6: 1 | D6: 190400
A7: Total 24K Global Logistics SAS | C7: 3 | D7: 6121360
A8: ACI Proyectos SAS | B8: 108806 | C8: 1 | D8: 166600
B9: 109005 | C9: 1 | D9: 135931320
B10: 109088 | C10: 1 | D10: 380359.7
B11: 109089 | C11: 1 | D11: 76517
A12: Total ACI Proyectos SAS | C12: 4 | D12: 1.365548e+08
A13: Adecco Colombia S A | B13: 108489 | C13: 1 | D13: 208250
A14: Total Adecco Colombia S A | C14: 1 | D14: 208250
A15: Adecco Servicios Colombia S A | B15: 108487 | C15: 1 | D15: 141610
B16: 108760 | C16: 1 | D16: 6090580
A17: Total Adecco Servicios Colombia S A | C17: 2 | D17: 6232190
A18: Administradora Country SAS | B18: 108883 | C18: 1 | D18: 285600
B19: 108968 | C19: 1 | D19: 10886333
B20: 109146 | C20: 1 | D20: 2482935
A21: Total Administradora Country SAS | C21: 3 | D21: 13654868
A22: Agencia De Aduanas Abc Repecev SAS Nivel 1 | B22: 109179 | C22: 1 | D22: 345100
B23: 109180 | C23: 1 | D23: 454580
B24: 109181 | C24: 1 | D24: 34510
B25: 109182 | C25: 1 | D25: 34510
A26: Total Agencia De Aduanas Abc Repecev SAS Nivel 1 | C26: 4 | D26: 868700
A27: Agricultura Y Servicios S A S | B27: 108671 | C27: 1 | D27: 14358540
B28: 108983 | C28: 1 | D28: 754460
A29: Total Agricultura Y Servicios S A S | C29: 2 | D29: 15113000
A30: Agrointegral Andina SAS | B30: 108670 | C30: 1 | D30: 14358540
B31: 108768 | C31: 1 | D31: 476000
B32: 108984 | C32: 1 | D32: 841330
A33: Total Agrointegral Andina SAS | C33: 3 | D33: 15675870
A34: Algranel SA | B34: 107703 | C34: 1 | D34: 535500
B35: 107712 | C35: 1 | D35: 3080435.2
B36: 107841 | C36: 1 | D36: 4270435.2
B37: 108032 | C37: 1 | D37: 428400
B38: 108129 | C38: 1 | D38: 982365.23
A39: Total Algranel SA | C39: 5 | D39: 9297135.6
A40: Alimentos Balanceados Tequendama SA Albateq SA | B40: 109220 | C40: 1 | D40: 1763118.3
A41: Total Alimentos Balanceados Tequendama SA Albateq SA | C41: 1 | D41: 1763118.3
...

Sheet PAGAS EN SISTEMA
A1: YA PAGA EN SISTEMA | B1: (en blanco)
A3: Nombre Receptor | B3: Folio | C3: Cuenta de YA PAGA EN SISTEMA | D3: Suma de Total
A4: 24K Global Logistics SAS | B4: 108175 | D4: 5408550
B5: 108503 | D5: 522410
B6: 108623 | D6: 190400
A7: Total 24K Global Logistics SAS | D7: 6121360
A8: ACI Proyectos SAS | B8: 108806 | D8: 166600
B9: 109005 | D9: 135931320
B10: 109088 | D10: 380359.7
B11: 109089 | D11: 76517
A12: Total ACI Proyectos SAS | D12: 1.365548e+08
A13: Actual Colombia Inmobiliaria SAS | B13: 108057 | D13: 1392300
A14: Total Actual Colombia Inmobiliaria SAS | D14: 1392300
A15: Adecco Colombia S A | B15: 108141 | D15: 433160
B16: 108489 | D16: 208250
A17: Total Adecco Colombia S A | D17: 641410
A18: Adecco Servicios Colombia S A | B18: 108019 | D18: 387940
B19: 108140 | D19: 3855600
B20: 108487 | D20: 141610
B21: 108760 | D21: 6090580
A22: Total Adecco Servicios Colombia S A | D22: 10475730
A23: Administradora Clinica La Colina S A S | B23: 108313 | D23: 3525589.2
A24: Total Administradora Clinica La Colina S A S | D24: 3525589.2
A25: Administradora Country SAS | B25: 107955 | D25: 1155180.6
B26: 108883 | D26: 285600
B27: 108968 | D27: 10886333
B28: 109146 | D28: 2482935
A29: Total Administradora Country SAS | D29: 14810049
A30: Agencia De Aduanas Abc Repecev SAS Nivel 1 | B30: 109179 | D30: 345100
B31: 109180 | D31: 454580
B32: 109181 | D32: 34510
B33: 109182 | D33: 34510
A34: Total Agencia De Aduanas Abc Repecev SAS Nivel 1 | D34: 868700
A35: Agricultura Y Servicios S A S | B35: 108671 | D35: 14358540
B36: 108983 | D36: 754460
A37: Total Agricultura Y Servicios S A S | D37: 15113000
A38: Agrointegral Andina SAS | B38: 108670 | D38: 14358540
B39: 108768 | D39: 476000
B40: 108984 | D40: 841330
A41: Total Agrointegral Andina SAS | D41: 15675870
...
